Workbook

Sheet df
A1: FANTAPEPE | C1: ORTEZZANO | E1: MONTELPARO | G1: FANTALEONE
A2: squadra00 | C2: squadra10 | E2: squadra20 | G2: squadra30
A3: squadra01 | C3: squadra11 | E3: squadra21 | G3: squadra31
A4: squadra02 | C4: squadra12 | E4: squadra22 | G4: squadra32
A5: squadra03 | C5: squadra13 | E5: squadra23 | G5: squadra33
A6: squadra04 | C6: squadra14 | E6: squadra24 | G6: squadra34
A7: squadra05 | C7: squadra15 | E7: squadra25 | G7: squadra35
A8: squadra06 | C8: squadra16 | E8: squadra26 | G8: squadra36
A9: squadra07 | C9: squadra17 | E9: squadra27 | G9: squadra37
A10: squadra08 | C10: squadra18 | E10: squadra28 | G10: squadra38
A11: squadra09 | C11: squadra19 | E11: squadra29 | G11: squadra39

Sheet DATASET
A1: FANTAPEPE | C1: ORTEZZANO | E1: MONTELPARO | G1: FANTALEONE | J1: Pc | K1: MARTINEZ L. | L1: INT
A2: Chicago Hasbulls | C2: Atletico Viperetta | E2: Pich Saint Germain | G2: Berlusca Dortmund | J2: Pc | K2: THURAM | L2: INT
A3: Real Lekkoba | C3: Mestieranti alla Better | E3: Zapdoria F.C. | G3: ReaL Fantonio | J3: Pc | K3: KEAN | L3: FIO
A4: FC LONGOBARDA | C4: Ahh poesse | E4: Real ZeLo | G4: As LucaGorets | J4: Pc | K4: DAVID | L4: JUV
A5: bomberini | C5: salumificio cardinali | E5: Hillboyss | G5: FC Arrisse | J5: A | K5: LEAO | L5: MIL
A6: PETRUS | C6: Horto Muso Zorteam | E6: Fc Increduli | G6: Forche di Roso FC | J6: C, T | K6: MCTOMINAY | L6: NAP
A7: Pepinho City | C7: Sotto per il Coco | E7: AC Clitoristo | G7: FantAllegri | J7: T, A | K7: PULISIC | L7: MIL
A8: AvelLino Banfi | C8: AteGamE | E8: SPAL Letta Fc | G8: TheStars94 | J8: Pc | K8: HOJLUND | L8: NAP
A9: Vojvodka liscia | C9: CamerierCarlo | E9: Fusbana | G9: F.C. Chiappe d ORO | J9: T, A | K9: PAZ N. | L9: COM
A10: AC Nostalgici 1922 | C10: Equitalia SpA | E10: PEPE SCANNATU | G10: FC Polidem | J10: A | K10: YILDIZ | L10: JUV
A11: Bayern Muten | C11: FC Demepoli | E11: FC Arrisse Junior | G11: NAPA U | J11: Pc | K11: CASTELLANOS | L11: LAZ
J12: W, A | K12: ORSOLINI | L12: BOL
J13: W, A | K13: ZACCAGNI | L13: LAZ
J14: Pc | K14: FERGUSON E. | L14: ROM
J15: A | K15: SOULÈ | L15: ROM
J16: A | K16: BERARDI | L16: SAS
J17: T, A | K17: GUDMUNDSSON A. | L17: FIO
J18: T | K18: DE BRUYNE | L18: NAP
J19: Pc | K19: SCAMACCA | L19: ATA
J20: A | K20: DYBALA | L20: ROM
J21: Por | K21: DI GREGORIO | L21: JUV
J22: Por | K22: MAIGNAN | L22: MIL
J23: Por | K23: SOMMER | L23: INT
... J533: Pc | K533: SKJELLERUP | L533: SAS

Sheet Eliminazione diretta
B2: PLAYOFF | C2: ANDATA | D2: RITORNO | E2: TOTALE | G2: OTTAVI | H2: ANDATA | I2: RITORNO | J2: TOTALE | M2: QUARTI | N2: ANDATA | O2: RITORNO | P2: TOTALE | S2: SEMIFINALI | T2: ANDATA | U2: RITORNO | V2: TOTALE | Y2: FINALE
B3: Chicago Hasbulls (22) | C3: 2 (72.0) | D3: 0 (64.5) | E3: 2 (136.5) | G3: Zapdoria F.C. (11) | H3: 3 (76.5) | I3: 3 (76.0) | J3: 6 (152.5)
B4: Zapdoria F.C. (11) | C4: 3 (74.5) | D4: 0 (65.0) | E4: 3 (139.5) | G4: Bayern Muten (6) | H4: 1 (68.0) | I4: 0 (65.0) | J4: 1 (133.0)
M5: Zapdoria F.C. (11) | N5: 0 (65.0) | O5: 2 (70.5) | P5: 2 (135.5)
M6: AC Nostalgici 1922 (13) | N6: 1 (69.0) | O6: 2 (70.0) | P6: 3 (139.0)
B7: SPAL Letta Fc (20) | C7: 1 (66.0) | D7: 0 (55.0) | E7: 1 (121) | G7: AC Nostalgici 1922 (13) | H7: 0 (65.5) | I7: 2 (70.0) | J7: 2 (135.5)
B8: AC Nostalgici 1922 (13) | C8: 1 (69.0) | D8: 1 (69.0) | E8: 2 (138) | G8: FC Arrisse (3) | H8: 1 (67.5) | I8: 1 (67.5) | J8: 2 (135.0)
S9: AC Nostalgici 1922 (13) | T9: 0 (63.5) | U9: 0 (61.5) | V9: 0 (125.0)
S10: Fusbana (1) | T10: 1 (69.5) | U10: 1 (69.0) | V10: 2 (138.5)
B11: Forche di Roso FC (24) | C11: 1 (69.0) | D11: 0 (65.5) | E11: 1 (134.5) | G11: FC Polidem (9) | H11: 3 (76.0) | I11: 2 (70.0) | J11: 5 (146.0)
B12: FC Polidem (9) | C12: 3 (75.0) | D12: 2 (72.0) | E12: 5 (147) | G12: Mestieranti alla Better (8) | H12: 2 (72.5) | I12: 1 (67.5) | J12: 3 (140.0)
M13: FC Polidem (9) | N13: 2 (73.5) | O13: 0 (60.5) | P13: 2 (133.5)
M14: Fusbana (1) | N14: 3 (76.0) | O14: 0 (63.0) | P14: 3 (139.0)
B15: ReaL Fantonio (18) | C15: 5 (84.0) | D15: 2 (73.0) | E15: 7 (157) | G15: ReaL Fantonio (18) | H15: 1 (67.0) | I15: 0 (57.5) | J15: 1 (124.5)
B16: Pepinho City (15) | C16: 2 (73.5) | D16: 1 (67.5) | E16: 3 (141) | G16: Fusbana (1) | H16: 0 (61.0) | I16: 4 (80.5) | J16: 4 (141.5)
Y17: Fusbana (1) | Z17: 1 (68.0)
Y18: Vojvodka liscia (5) | Z18: 2 (72.5)
B19: Real ZeLo (21) | C19: 1 (68.5) | D19: 2 (73.0) | E19: 3 (141.5) | G19: Real ZeLo (21) | H19: 2 (70.5) | I19: 0 (61.0) | J19: 2 (131.5)
B20: TheStars94 (12) | C20: 0 (61.5) | D20: 0 (64.0) | E20: 0 (125.5) | G20: Vojvodka liscia (5) | H20: 3 (75.5) | I20: 1 (66.5) | J20: 4 (142.0)
M21: Vojvodka liscia (5) | N21: 2 (72.0) | O21: 1 (69.5) | P21: 3 (141.5)
M22: FC Demepoli (4) | N22: 0 (61.0) | O22: 0 (60.5) | P22: 0 (121.5)
B23: Hillboyss (19) | C23: 2 (73.0) | D23: 0 (62.5) | E23: 2 (135.5) | G23: Hillboyss (19) | H23: 1 (69.5) | I23: 0 (65.5) | J23: 1 (135.0)
B24: NAPA U (14) | C24: 0 (64.5) | D24: 1 (66.0) | E24: 1 (130.5) | G24: FC Demepoli (4) | H24: 1 (68.0) | I24: 1 (66.5) | J24: 2 (134.5)
S25: Vojvodka liscia (5) | T25: 3 (74.5) | U25: 4 (79.5) | V25: 7 (154.0)
S26: Pich Saint Germain (16) | T26: 1 (68.5) | U26: 1 (67.0) | V26: 2 (135.5)
B27: PEPE SCANNATU (23) | C27: 0 (63.5) | D27: 0 (58.5) | E27: 0 (122) | G27: Equitalia SpA (10) | H27: 0 (60.5) | I27: 0 (60.5) | J27: 0 (121.0)
B28: Equitalia SpA (10) | C28: 2 (71.5) | D28: 0 (62.5) | E28: 2 (134) | G28: PETRUS (7) | H28: 1 (69.5) | I28: 1 (67.0) | J28: 2 (136.5)
M29: PETRUS (7) | N29: 0 (63.5) | O29: 1 (69.5) | P29: 1 (133.0)
M30: Pich Saint Germain (16) | N30: 3 (77.5) | O30: 1 (67.5) | P30: 4 (145.0)
B31: CamerierCarlo (17) | C31: 1 (68.5) | D31: 0 (65.5) | E31: 1 (134) | G31: Pich Saint Germain (16) | H31: 4 (79.5) | I31: 1 (66.5) | J31: 5 (146.0)
B32: Pich Saint Germain (16) | C32: 1 (69.0) | D32: 1 (67.0) | E32: 2 (136) | G32: Ahh poesse (2) | H32: 0 (60.0) | I32: 2 (71.5) | J32: 2 (131.5)

Sheet Classifica
B2: # | C2: Nome | D2: Punti | E2: Punteggio | F2: Vittorie | G2: Pareggi | H2: Sconfitte | I2: Gol Fatti | J2: Gol Subiti
B3: 1 | C3: Fusbana | D3: 21 | E3: 710.5 | F3: 7 | G3: 0 | H3: 3 | I3: 19 | J3: 11 | L3: Qualificazione diretta agli ottavi di finale
B4: 2 | C4: Ahh poesse | D4: 20 | E4: 715.5 | F4: 6 | G4: 2 | H4: 2 | I4: 21 | J4: 14
B5: 3 | C5: FC Arrisse | D5: 20 | E5: 701 | F5: 6 | G5: 2 | H5: 2 | I5: 16 | J5: 10 | L5: Qualificazione ai sedicesimi di finale
B6: 4 | C6: FC Demepoli | D6: 19 | E6: 724.5 | F6: 5 | G6: 4 | H6: 1 | I6: 21 | J6: 11
B7: 5 | C7: Vojvodka liscia | D7: 19 | E7: 705.5 | F7: 6 | G7: 1 | H7: 3 | I7: 18 | J7: 11
B8: 6 | C8: Bayern Muten | D8: 18 | E8: 703.5 | F8: 5 | G8: 3 | H8: 2 | I8: 18 | J8: 11
B9: 7 | C9: PETRUS | D9: 18 | E9: 702 | F9: 5 | G9: 3 | H9: 2 | I9: 17 | J9: 11
B10: 8 | C10: Mestieranti alla Better | D10: 17 | E10: 692 | F10: 5 | G10: 2 | H10: 3 | I10: 13 | J10: 12
B11: 9 | C11: FC Polidem | D11: 17 | E11: 691 | F11: 5 | G11: 2 | H11: 3 | I11: 12 | J11: 10
B12: 10 | C12: Equitalia SpA | D12: 16 | E12: 718 | F12: 5 | G12: 1 | H12: 4 | I12: 20 | J12: 16
B13: 11 | C13: Zapdoria F.C. | D13: 16 | E13: 708 | F13: 4 | G13: 4 | H13: 2 | I13: 18 | J13: 14
B14: 12 | C14: TheStars94 | D14: 16 | E14: 707 | F14: 5 | G14: 1 | H14: 4 | I14: 17 | J14: 16
B15: 13 | C15: AC Nostalgici 1922 | D15: 16 | E15: 695.5 | F15: 4 | G15: 4 | H15: 2 | I15: 15 | J15: 12
B16: 14 | C16: NAPA U | D16: 15 | E16: 689.5 | F16: 4 | G16: 3 | H16: 3 | I16: 14 | J16: 11
B17: 15 | C17: Pepinho City | D17: 15 | E17: 685 | F17: 4 | G17: 3 | H17: 3 | I17: 14 | J17: 10
... B42: 40 | C42: Horto Muso Zorteam | D42: 6 | E42: 663.5 | F42: 1 | G42: 3 | H42: 6 | I42: 7 | J42: 16

Sheet Calendario
B2: Giornata 1 | E2: Serie A: Giornata4
B3: AC Clitoristo | C3: 2 | D3: 1 | E3: Pepinho City
C4: 71 | D4: 66
B5: AC Nostalgici 1922 | C5: 1 | D5: 4 | E5: Fusbana
C6: 67 | D6: 78.5
B7: Ahh poesse | C7: 0 | D7: 0 | E7: F.C. Chiappe d ORO
C8: 64 | D8: 62
B9: As LucaGorets | C9: 1 | D9: 2 | E9: SPAL Letta Fc
C10: 66.5 | D10: 71
B11: AvelLino Banfi | C11: 2 | D11: 0 | E11: Mestieranti alla Better
C12: 70.5 | D12: 64
B13: Berlusca Dortmund | C13: 1 | D13: 1 | E13: Bayern Muten
C14: 69.5 | D14: 68.5
B15: CamerierCarlo | C15: 4 | D15: 1 | E15: FC Arrisse Junior
C16: 78 | D16: 68
B17: Chicago Hasbulls | C17: 1 | D17: 1 | E17: AteGamE
C18: 68 | D18: 66
B19: Equitalia SpA | C19: 0 | D19: 2 | E19: FC Arrisse
C20: 60.5 | D20: 73
B21: FC Demepoli | C21: 6 | D21: 1 | E21: Real ZeLo
C22: 86 | D22: 68.5
B23: FC LONGOBARDA | C23: 4 | D23: 4 | E23: Forche di Roso FC
C24: 81 | D24: 79
B25: FantAllegri | C25: 2 | D25: 1 | E25: Real Lekkoba
C26: 72 | D26: 67.5
B27: Hillboyss | C27: 1 | D27: 1 | E27: bomberini
C28: 67.5 | D28: 66
B29: Horto Muso Zorteam | C29: 1 | D29: 2 | E29: Zapdoria F.C.
C30: 68.5 | D30: 73
B31: NAPA U | C31: 1 | D31: 2 | E31: PEPE SCANNATU
C32: 67 | D32: 70
B33: PETRUS | C33: 1 | D33: 0 | E33: Pich Saint Germain
C34: 66.5 | D34: 65
B35: Sotto per il Coco | C35: 2 | D35: 0 | E35: FC Polidem
C36: 70.5 | D36: 65.5
B37: TheStars94 | C37: 3 | D37: 0 | E37: Fc Increduli
C38: 74 | D38: 63
B39: Vojvodka liscia | C39: 3 | D39: 1 | E39: Atletico Viperetta
C40: 75.5 | D40: 67
B41: salumificio cardinali | C41: 4 | D41: 2 | E41: ReaL Fantonio
...

Sheet Rose
A1: AvelLino Banfi | E1: Pepinho City | I1: Vojvodka liscia | M1: Real Lekkoba | Q1: PETRUS | U1: AC Nostalgici 1922 | Y1: Chicago Hasbulls | AC1: Bayern Muten | AG1: bomberini | AK1: FC LONGOBARDA | AO1: Sotto per il Coco | AS1: CamerierCarlo | AW1: salumificio cardinali | BA1: Ahh poesse | BE1: Mestieranti alla Better | BI1: Equitalia SpA | BM1: Horto Muso Zorteam | BQ1: AteGamE | BU1: Atletico Viperetta | BY1: FC Demepoli | CC1: Pich Saint Germain | CG1: AC Clitoristo | CK1: SPAL Letta Fc | CO1: PEPE SCANNATU | CS1: FC Arrisse Junior | CW1: Fusbana | DA1: Fc Increduli | DE1: Zapdoria F.C. | DI1: Real ZeLo | DM1: Hillboyss | DQ1: As LucaGorets | DU1: Forche di Roso FC | DY1: TheStars94 | EC1: FC Polidem | EG1: FC Arrisse | EK1: FantAllegri | EO1: F.C. Chiappe d ORO | ES1: NAPA U | EW1: ReaL Fantonio | FA1: Berlusca Dortmund
A2: NOME | B2: SQUADRA | C2: RUOLO | E2: NOME | F2: SQUADRA | G2: RUOLO | I2: NOME | J2: SQUADRA | K2: RUOLO | M2: NOME | N2: SQUADRA | O2: RUOLO | Q2: NOME | R2: SQUADRA | S2: RUOLO | U2: NOME | V2: SQUADRA | W2: RUOLO | Y2: NOME | Z2: SQUADRA | AA2: RUOLO | AC2: NOME | AD2: SQUADRA | AE2: RUOLO | AG2: NOME | AH2: SQUADRA | AI2: RUOLO | AK2: NOME | AL2: SQUADRA | AM2: RUOLO | AO2: NOME | AP2: SQUADRA | AQ2: RUOLO | AS2: NOME | AT2: SQUADRA | AU2: RUOLO | AW2: NOME | AX2: SQUADRA | AY2: RUOLO | BA2: NOME | BB2: SQUADRA | BC2: RUOLO | BE2: NOME | BF2: SQUADRA | BG2: RUOLO | BI2: NOME | BJ2: SQUADRA | BK2: RUOLO | BM2: NOME | BN2: SQUADRA | BO2: RUOLO | BQ2: NOME | BR2: SQUADRA | BS2: RUOLO | BU2: NOME | BV2: SQUADRA | BW2: RUOLO | BY2: NOME | BZ2: SQUADRA | CA2: RUOLO | CC2: NOME | CD2: SQUADRA | CE2: RUOLO | CG2: NOME | CH2: SQUADRA | CI2: RUOLO | CK2: NOME | CL2: SQUADRA | CM2: RUOLO | CO2: NOME | CP2: SQUADRA | CQ2: RUOLO | CS2: NOME | CT2: SQUADRA | CU2: RUOLO | CW2: NOME | CX2: SQUADRA | CY2: RUOLO | DA2: NOME | DB2: SQUADRA | DC2: RUOLO | DE2: NOME | DF2: SQUADRA | DG2: RUOLO | DI2: NOME | DJ2: SQUADRA | DK2: RUOLO | DM2: NOME | DN2: SQUADRA | DO2: RUOLO | DQ2: NOME | DR2: SQUADRA | DS2: RUOLO | DU2: NOME | DV2: SQUADRA | DW2: RUOLO | DY2: NOME | DZ2: SQUADRA | EA2: RUOLO | EC2: NOME | ED2: SQUADRA | EE2: RUOLO | EG2: NOME | EH2: SQUADRA | EI2: RUOLO | EK2: NOME | EL2: SQUADRA | EM2: RUOLO | EO2: NOME | EP2: SQUADRA | EQ2: RUOLO | ES2: NOME | ET2: SQUADRA | EU2: RUOLO | EW2: NOME | EX2: SQUADRA | EY2: RUOLO | FA2: NOME | FB2: SQUADRA | FC2: RUOLO
A3: CARNESECCHI | B3: {=INDIRECT(ADDRESS(MATCH(A3,DATASET!$K:$K,0),12,,,"DATASET"))} -> ATA | C3: {=INDIRECT(ADDRESS(MATCH(A3,DATASET!$K:$K,0),10,,,"DATASET"))} -> Por | E3: GOLLINI | F3: {=INDIRECT(ADDRESS(MATCH(E3,DATASET!$K:$K,0),12,,,"DATASET"))} -> ROM | G3: {=INDIRECT(ADDRESS(MATCH(E3,DATASET!$K:$K,0),10,,,"DATASET"))} -> Por | I3: ISRAEL | J3: {=INDIRECT(ADDRESS(MATCH(I3,DATASET!$K:$K,0),12,,,"DATASET"))} -> TOR | K3: {=INDIRECT(ADDRESS(MATCH(I3,DATASET!$K:$K,0),10,,,"DATASET"))} -> Por | M3: CONTINI | N3: {=INDIRECT(ADDRESS(MATCH(M3,DATASET!$K:$K,0),12,,,"DATASET"))} -> NAP | O3: {=INDIRECT(ADDRESS(MATCH(M3,DATASET!$K:$K,0),10,,,"DATASET"))} -> Por | Q3: DI GREGORIO | R3: {=INDIRECT(ADDRESS(MATCH(Q3,DATASET!$K:$K,0),12,,,"DATASET"))} -> JUV | S3: {=INDIRECT(ADDRESS(MATCH(Q3,DATASET!$K:$K,0),10,,,"DATASET"))} -> Por | U3: BUTEZ | V3: {=INDIRECT(ADDRESS(MATCH(U3,DATASET!$K:$K,0),12,,,"DATASET"))} -> COM | W3: {=INDIRECT(ADDRESS(MATCH(U3,DATASET!$K:$K,0),10,,,"DATASET"))} -> Por | Y3: CAPRILE | Z3: {=INDIRECT(ADDRESS(MATCH(Y3,DATASET!$K:$K,0),12,,,"DATASET"))} -> CAG | AA3: {=INDIRECT(ADDRESS(MATCH(Y3,DATASET!$K:$K,0),10,,,"DATASET"))} -> Por | AC3: MARTINEZ JO. | AD3: {=INDIRECT(ADDRESS(MATCH(AC3,DATASET!$K:$K,0),12,,,"DATASET"))} -> INT | AE3: {=INDIRECT(ADDRESS(MATCH(AC3,DATASET!$K:$K,0),10,,,"DATASET"))} -> Por | AG3: AUDERO | AH3: {=INDIRECT(ADDRESS(MATCH(AG3,DATASET!$K:$K,0),12,,,"DATASET"))} -> CRE | AI3: {=INDIRECT(ADDRESS(MATCH(AG3,DATASET!$K:$K,0),10,,,"DATASET"))} -> Por | AK3: FALCONE | AL3: {=INDIRECT(ADDRESS(MATCH(AK3,DATASET!$K:$K,0),12,,,"DATASET"))} -> LEC | AM3: {=INDIRECT(ADDRESS(MATCH(AK3,DATASET!$K:$K,0),10,,,"DATASET"))} -> Por | AO3: CAPRILE | AP3: {=INDIRECT(ADDRESS(MATCH(AO3,DATASET!$K:$K,0),12,,,"DATASET"))} -> CAG | AQ3: {=INDIRECT(ADDRESS(MATCH(AO3,DATASET!$K:$K,0),10,,,"DATASET"))} -> Por | AS3: CARNESECCHI | AT3: {=INDIRECT(ADDRESS(MATCH(AS3,DATASET!$K:$K,0),12,,,"DATASET"))} -> ATA | AU3: {=INDIRECT(ADDRESS(MATCH(AS3,DATASET!$K:$K,0),10,,,"DATASET"))} -> Por | AW3: LEALI | AX3: {=INDIRECT(ADDRESS(MATCH(AW3,DATASET!$K:$K,0),12,,,"DATASET"))} -> GEN | AY3: {=INDIRECT(ADDRESS(MATCH(AW3,DATASET!$K:$K,0),10,,,"DATASET"))} -> Por | BA3: DE GEA | BB3: {=INDIRECT(ADDRESS(MATCH(BA3,DATASET!$K:$K,0),12,,,"DATASET"))} -> FIO | BC3: {=INDIRECT(ADDRESS(MATCH(BA3,DATASET!$K:$K,0),10,,,"DATASET"))} -> Por | BE3: BUTEZ | BF3: {=INDIRECT(ADDRESS(MATCH(BE3,DATASET!$K:$K,0),12,,,"DATASET"))} -> COM | BG3: {=INDIRECT(ADDRESS(MATCH(BE3,DATASET!$K:$K,0),10,,,"DATASET"))} -> Por | BI3: MARTINEZ JO. | BJ3: {=INDIRECT(ADDRESS(MATCH(BI3,DATASET!$K:$K,0),12,,,"DATASET"))} -> INT | BK3: {=INDIRECT(ADDRESS(MATCH(BI3,DATASET!$K:$K,0),10,,,"DATASET"))} -> Por | BM3: MERET | BN3: {=INDIRECT(ADDRESS(MATCH(BM3,DATASET!$K:$K,0),12,,,"DATASET"))} -> NAP | BO3: {=INDIRECT(ADDRESS(MATCH(BM3,DATASET!$K:$K,0),10,,,"DATASET"))} -> Por | BQ3: ISRAEL | BR3: {=INDIRECT(ADDRESS(MATCH(BQ3,DATASET!$K:$K,0),12,,,"DATASET"))} -> TOR | BS3: {=INDIRECT(ADDRESS(MATCH(BQ3,DATASET!$K:$K,0),10,,,"DATASET"))} -> Por | BU3: AUDERO | BV3: {=INDIRECT(ADDRESS(MATCH(BU3,DATASET!$K:$K,0),12,,,"DATASET"))} -> CRE | BW3: {=INDIRECT(ADDRESS(MATCH(BU3,DATASET!$K:$K,0),10,,,"DATASET"))} -> Por | BY3: SVILAR | BZ3: {=INDIRECT(ADDRESS(MATCH(BY3,DATASET!$K:$K,0),12,,,"DATASET"))} -> ROM | CA3: {=INDIRECT(ADDRESS(MATCH(BY3,DATASET!$K:$K,0),10,,,"DATASET"))} -> Por | CC3: MAIGNAN | CD3: {=INDIRECT(ADDRESS(MATCH(CC3,DATASET!$K:$K,0),12,,,"DATASET"))} -> MIL | CE3: {=INDIRECT(ADDRESS(MATCH(CC3,DATASET!$K:$K,0),10,,,"DATASET"))} -> Por | CG3: GOLLINI | CH3: {=INDIRECT(ADDRESS(MATCH(CG3,DATASET!$K:$K,0),12,,,"DATASET"))} -> ROM | CI3: {=INDIRECT(ADDRESS(MATCH(CG3,DATASET!$K:$K,0),10,,,"DATASET"))} -> Por | CK3: DI GENNARO | CL3: {=INDIRECT(ADDRESS(MATCH(CK3,DATASET!$K:$K,0),12,,,"DATASET"))} -> INT | CM3: {=INDIRECT(ADDRESS(MATCH(CK3,DATASET!$K:$K,0),10,,,"DATASET"))} -> Por | CO3: FALCONE | CP3: {=INDIRECT(ADDRESS(MATCH(CO3,DATASET!$K:$K,0),12,,,"DATASET"))} -> LEC | CQ3: {=INDIRECT(ADDRESS(MATCH(CO3,DATASET!$K:$K,0),10,,,"DATASET"))} -> Por | CS3: FURLANETTO | CT3: {=INDIRECT(ADDRESS(MATCH(CS3,DATASET!$K:$K,0),12,,,"DATASET"))} -> LAZ | CU3: {=INDIRECT(ADDRESS(MATCH(CS3,DATASET!$K:$K,0),10,,,"DATASET"))} -> Por | CW3: AUDERO | CX3: {=INDIRECT(ADDRESS(MATCH(CW3,DATASET!$K:$K,0),12,,,"DATASET"))} -> CRE | CY3: {=INDIRECT(ADDRESS(MATCH(CW3,DATASET!$K:$K,0),10,,,"DATASET"))} -> Por | DA3: BUTEZ | DB3: {=INDIRECT(ADDRESS(MATCH(DA3,DATASET!$K:$K,0),12,,,"DATASET"))} -> COM | DC3: {=INDIRECT(ADDRESS(MATCH(DA3,DATASET!$K:$K,0),10,,,"DATASET"))} -> Por | DE3: MERET | DF3: {=INDIRECT(ADDRESS(MATCH(DE3,DATASET!$K:$K,0),12,,,"DATASET"))} -> NAP | DG3: {=INDIRECT(ADDRESS(MATCH(DE3,DATASET!$K:$K,0),10,,,"DATASET"))} -> Por | DI3: CAPRILE | DJ3: {=INDIRECT(ADDRESS(MATCH(DI3,DATASET!$K:$K,0),12,,,"DATASET"))} -> CAG | DK3: {=INDIRECT(ADDRESS(MATCH(DI3,DATASET!$K:$K,0),10,,,"DATASET"))} -> Por | DM3: CONTINI | DN3: {=INDIRECT(ADDRESS(MATCH(DM3,DATASET!$K:$K,0),12,,,"DATASET"))} -> NAP | DO3: {=INDIRECT(ADDRESS(MATCH(DM3,DATASET!$K:$K,0),10,,,"DATASET"))} -> Por | DQ3: AUDERO | DR3: {=INDIRECT(ADDRESS(MATCH(DQ3,DATASET!$K:$K,0),12,,,"DATASET"))} -> CRE | DS3: {=INDIRECT(ADDRESS(MATCH(DQ3,DATASET!$K:$K,0),10,,,"DATASET"))} -> Por | DU3: BUTEZ | DV3: {=INDIRECT(ADDRESS(MATCH(DU3,DATASET!$K:$K,0),12,,,"DATASET"))} -> COM | DW3: {=INDIRECT(ADDRESS(MATCH(DU3,DATASET!$K:$K,0),10,,,"DATASET"))} -> Por | DY3: CARNESECCHI | DZ3: {=INDIRECT(ADDRESS(MATCH(DY3,DATASET!$K:$K,0),12,,,"DATASET"))} -> ATA | EA3: {=INDIRECT(ADDRESS(MATCH(DY3,DATASET!$K:$K,0),10,,,"DATASET"))} -> Por | EC3: DI GENNARO | ED3: {=INDIRECT(ADDRESS(MATCH(EC3,DATASET!$K:$K,0),12,,,"DATASET"))} -> INT | EE3: {=INDIRECT(ADDRESS(MATCH(EC3,DATASET!$K:$K,0),10,,,"DATASET"))} -> Por | EG3: MANDAS | EH3: {=INDIRECT(ADDRESS(MATCH(EG3,DATASET!$K:$K,0),12,,,"DATASET"))} -> LAZ | EI3: {=INDIRECT(ADDRESS(MATCH(EG3,DATASET!$K:$K,0),10,,,"DATASET"))} -> Por | EK3: DI GREGORIO | EL3: {=INDIRECT(ADDRESS(MATCH(EK3,DATASET!$K:$K,0),12,,,"DATASET"))} -> JUV | EM3: {=INDIRECT(ADDRESS(MATCH(EK3,DATASET!$K:$K,0),10,,,"DATASET"))} -> Por | EO3: CAPRILE | EP3: {=INDIRECT(ADDRESS(MATCH(EO3,DATASET!$K:$K,0),12,,,"DATASET"))} -> CAG | EQ3: {=INDIRECT(ADDRESS(MATCH(EO3,DATASET!$K:$K,0),10,,,"DATASET"))} -> Por | ES3: LEALI | ET3: {=INDIRECT(ADDRESS(MATCH(ES3,DATASET!$K:$K,0),12,,,"DATASET"))} -> GEN | EU3: {=INDIRECT(ADDRESS(MATCH(ES3,DATASET!$K:$K,0),10,,,"DATASET"))} -> Por | EW3: MAIGNAN | EX3: {=INDIRECT(ADDRESS(MATCH(EW3,DATASET!$K:$K,0),12,,,"DATASET"))} -> MIL | EY3: {=INDIRECT(ADDRESS(MATCH(EW3,DATASET!$K:$K,0),10,,,"DATASET"))} -> Por | FA3: MONTIPÒ | FB3: {=INDIRECT(ADDRESS(MATCH(FA3,DATASET!$K:$K,0),12,,,"DATASET"))} -> VER | FC3: {=INDIRECT(ADDRESS(MATCH(FA3,DATASET!$K:$K,0),10,,,"DATASET"))} -> Por
A4: SEMPER | B4: {=INDIRECT(ADDRESS(MATCH(A4,DATASET!$K:$K,0),12,,,"DATASET"))} -> PIS | C4: {=INDIRECT(ADDRESS(MATCH(A4,DATASET!$K:$K,0),10,,,"DATASET"))} -> Por | E4: SVILAR | F4: {=INDIRECT(ADDRESS(MATCH(E4,DATASET!$K:$K,0),12,,,"DATASET"))} -> ROM | G4: {=INDIRECT(ADDRESS(MATCH(E4,DATASET!$K:$K,0),10,,,"DATASET"))} -> Por | I4: MAIGNAN | J4: {=INDIRECT(ADDRESS(MATCH(I4,DATASET!$K:$K,0),12,,,"DATASET"))} -> MIL | K4: {=INDIRECT(ADDRESS(MATCH(I4,DATASET!$K:$K,0),10,,,"DATASET"))} -> Por | M4: MERET | N4: {=INDIRECT(ADDRESS(MATCH(M4,DATASET!$K:$K,0),12,,,"DATASET"))} -> NAP | O4: {=INDIRECT(ADDRESS(MATCH(M4,DATASET!$K:$K,0),10,,,"DATASET"))} -> Por | Q4: PERIN | R4: {=INDIRECT(ADDRESS(MATCH(Q4,DATASET!$K:$K,0),12,,,"DATASET"))} -> JUV | S4: {=INDIRECT(ADDRESS(MATCH(Q4,DATASET!$K:$K,0),10,,,"DATASET"))} -> Por | U4: LEALI | V4: {=INDIRECT(ADDRESS(MATCH(U4,DATASET!$K:$K,0),12,,,"DATASET"))} -> GEN | W4: {=INDIRECT(ADDRESS(MATCH(U4,DATASET!$K:$K,0),10,,,"DATASET"))} -> Por | Y4: DE GEA | Z4: {=INDIRECT(ADDRESS(MATCH(Y4,DATASET!$K:$K,0),12,,,"DATASET"))} -> FIO | AA4: {=INDIRECT(ADDRESS(MATCH(Y4,DATASET!$K:$K,0),10,,,"DATASET"))} -> Por | AC4: MURIC | AD4: {=INDIRECT(ADDRESS(MATCH(AC4,DATASET!$K:$K,0),12,,,"DATASET"))} -> SAS | AE4: {=INDIRECT(ADDRESS(MATCH(AC4,DATASET!$K:$K,0),10,,,"DATASET"))} -> Por | AG4: MANDAS | AH4: {=INDIRECT(ADDRESS(MATCH(AG4,DATASET!$K:$K,0),12,,,"DATASET"))} -> LAZ | AI4: {=INDIRECT(ADDRESS(MATCH(AG4,DATASET!$K:$K,0),10,,,"DATASET"))} -> Por | AK4: MONTIPÒ | AL4: {=INDIRECT(ADDRESS(MATCH(AK4,DATASET!$K:$K,0),12,,,"DATASET"))} -> VER | AM4: {=INDIRECT(ADDRESS(MATCH(AK4,DATASET!$K:$K,0),10,,,"DATASET"))} -> Por | AO4: MARTINEZ JO. | AP4: {=INDIRECT(ADDRESS(MATCH(AO4,DATASET!$K:$K,0),12,,,"DATASET"))} -> INT | AQ4: {=INDIRECT(ADDRESS(MATCH(AO4,DATASET!$K:$K,0),10,,,"DATASET"))} -> Por | AS4: OKOYE | AT4: {=INDIRECT(ADDRESS(MATCH(AS4,DATASET!$K:$K,0),12,,,"DATASET"))} -> UDI | AU4: {=INDIRECT(ADDRESS(MATCH(AS4,DATASET!$K:$K,0),10,,,"DATASET"))} -> Por | AW4: MANDAS | AX4: {=INDIRECT(ADDRESS(MATCH(AW4,DATASET!$K:$K,0),12,,,"DATASET"))} -> LAZ | AY4: {=INDIRECT(ADDRESS(MATCH(AW4,DATASET!$K:$K,0),10,,,"DATASET"))} -> Por | BA4: LEZZERINI | BB4: {=INDIRECT(ADDRESS(MATCH(BA4,DATASET!$K:$K,0),12,,,"DATASET"))} -> FIO | BC4: {=INDIRECT(ADDRESS(MATCH(BA4,DATASET!$K:$K,0),10,,,"DATASET"))} -> Por | BE4: DI GREGORIO | BF4: {=INDIRECT(ADDRESS(MATCH(BE4,DATASET!$K:$K,0),12,,,"DATASET"))} -> JUV | BG4: {=INDIRECT(ADDRESS(MATCH(BE4,DATASET!$K:$K,0),10,,,"DATASET"))} -> Por | BI4: MONTIPÒ | BJ4: {=INDIRECT(ADDRESS(MATCH(BI4,DATASET!$K:$K,0),12,,,"DATASET"))} -> VER | BK4: {=INDIRECT(ADDRESS(MATCH(BI4,DATASET!$K:$K,0),10,,,"DATASET"))} -> Por | BM4: MILINKOVIC-SAVIC V. | BN4: {=INDIRECT(ADDRESS(MATCH(BM4,DATASET!$K:$K,0),12,,,"DATASET"))} -> NAP | BO4: {=INDIRECT(ADDRESS(MATCH(BM4,DATASET!$K:$K,0),10,,,"DATASET"))} -> Por | BQ4: SEMPER | BR4: {=INDIRECT(ADDRESS(MATCH(BQ4,DATASET!$K:$K,0),12,,,"DATASET"))} -> PIS | BS4: {=INDIRECT(ADDRESS(MATCH(BQ4,DATASET!$K:$K,0),10,,,"DATASET"))} -> Por | BU4: MAIGNAN | BV4: {=INDIRECT(ADDRESS(MATCH(BU4,DATASET!$K:$K,0),12,,,"DATASET"))} -> MIL | BW4: {=INDIRECT(ADDRESS(MATCH(BU4,DATASET!$K:$K,0),10,,,"DATASET"))} -> Por | BY4: VASQUEZ D. | BZ4: {=INDIRECT(ADDRESS(MATCH(BY4,DATASET!$K:$K,0),12,,,"DATASET"))} -> ROM | CA4: {=INDIRECT(ADDRESS(MATCH(BY4,DATASET!$K:$K,0),10,,,"DATASET"))} -> Por | CC4: TERRACCIANO | CD4: {=INDIRECT(ADDRESS(MATCH(CC4,DATASET!$K:$K,0),12,,,"DATASET"))} -> MIL | CE4: {=INDIRECT(ADDRESS(MATCH(CC4,DATASET!$K:$K,0),10,,,"DATASET"))} -> Por | CG4: SVILAR | CH4: {=INDIRECT(ADDRESS(MATCH(CG4,DATASET!$K:$K,0),12,,,"DATASET"))} -> ROM | CI4: {=INDIRECT(ADDRESS(MATCH(CG4,DATASET!$K:$K,0),10,,,"DATASET"))} -> Por | CK4: MARTINEZ JO. | CL4: {=INDIRECT(ADDRESS(MATCH(CK4,DATASET!$K:$K,0),12,,,"DATASET"))} -> INT | CM4: {=INDIRECT(ADDRESS(MATCH(CK4,DATASET!$K:$K,0),10,,,"DATASET"))} -> Por | CO4: ISRAEL | CP4: {=INDIRECT(ADDRESS(MATCH(CO4,DATASET!$K:$K,0),12,,,"DATASET"))} -> TOR | CQ4: {=INDIRECT(ADDRESS(MATCH(CO4,DATASET!$K:$K,0),10,,,"DATASET"))} -> Por | CS4: MANDAS | CT4: {=INDIRECT(ADDRESS(MATCH(CS4,DATASET!$K:$K,0),12,,,"DATASET"))} -> LAZ | CU4: {=INDIRECT(ADDRESS(MATCH(CS4,DATASET!$K:$K,0),10,,,"DATASET"))} -> Por | CW4: DE GEA | CX4: {=INDIRECT(ADDRESS(MATCH(CW4,DATASET!$K:$K,0),12,,,"DATASET"))} -> FIO | CY4: {=INDIRECT(ADDRESS(MATCH(CW4,DATASET!$K:$K,0),10,,,"DATASET"))} -> Por | DA4: RAVAGLIA F. | DB4: {=INDIRECT(ADDRESS(MATCH(DA4,DATASET!$K:$K,0),12,,,"DATASET"))} -> BOL | DC4: {=INDIRECT(ADDRESS(MATCH(DA4,DATASET!$K:$K,0),10,,,"DATASET"))} -> Por | DE4: MILINKOVIC-SAVIC V. | DF4: {=INDIRECT(ADDRESS(MATCH(DE4,DATASET!$K:$K,0),12,,,"DATASET"))} -> NAP | DG4: {=INDIRECT(ADDRESS(MATCH(DE4,DATASET!$K:$K,0),10,,,"DATASET"))} -> Por | DI4: DI GREGORIO | DJ4: {=INDIRECT(ADDRESS(MATCH(DI4,DATASET!$K:$K,0),12,,,"DATASET"))} -> JUV | DK4: {=INDIRECT(ADDRESS(MATCH(DI4,DATASET!$K:$K,0),10,,,"DATASET"))} -> Por | DM4: MERET | DN4: {=INDIRECT(ADDRESS(MATCH(DM4,DATASET!$K:$K,0),12,,,"DATASET"))} -> NAP | DO4: {=INDIRECT(ADDRESS(MATCH(DM4,DATASET!$K:$K,0),10,,,"DATASET"))} -> Por | DQ4: DE GEA | DR4: {=INDIRECT(ADDRESS(MATCH(DQ4,DATASET!$K:$K,0),12,,,"DATASET"))} -> FIO | DS4: {=INDIRECT(ADDRESS(MATCH(DQ4,DATASET!$K:$K,0),10,,,"DATASET"))} -> Por | DU4: FALCONE | DV4: {=INDIRECT(ADDRESS(MATCH(DU4,DATASET!$K:$K,0),12,,,"DATASET"))} -> LEC | DW4: {=INDIRECT(ADDRESS(MATCH(DU4,DATASET!$K:$K,0),10,,,"DATASET"))} -> Por | DY4: ROSSI F. | DZ4: {=INDIRECT(ADDRESS(MATCH(DY4,DATASET!$K:$K,0),12,,,"DATASET"))} -> ATA | EA4: {=INDIRECT(ADDRESS(MATCH(DY4,DATASET!$K:$K,0),10,,,"DATASET"))} -> Por | EC4: MARTINEZ JO. | ED4: {=INDIRECT(ADDRESS(MATCH(EC4,DATASET!$K:$K,0),12,,,"DATASET"))} -> INT | EE4: {=INDIRECT(ADDRESS(MATCH(EC4,DATASET!$K:$K,0),10,,,"DATASET"))} -> Por | EG4: RAVAGLIA F. | EH4: {=INDIRECT(ADDRESS(MATCH(EG4,DATASET!$K:$K,0),12,,,"DATASET"))} -> BOL | EI4: {=INDIRECT(ADDRESS(MATCH(EG4,DATASET!$K:$K,0),10,,,"DATASET"))} -> Por | EK4: PERIN | EL4: {=INDIRECT(ADDRESS(MATCH(EK4,DATASET!$K:$K,0),12,,,"DATASET"))} -> JUV | EM4: {=INDIRECT(ADDRESS(MATCH(EK4,DATASET!$K:$K,0),10,,,"DATASET"))} -> Por | EO4: SVILAR | EP4: {=INDIRECT(ADDRESS(MATCH(EO4,DATASET!$K:$K,0),12,,,"DATASET"))} -> ROM | EQ4: {=INDIRECT(ADDRESS(MATCH(EO4,DATASET!$K:$K,0),10,,,"DATASET"))} -> Por | ES4: MERET | ET4: {=INDIRECT(ADDRESS(MATCH(ES4,DATASET!$K:$K,0),12,,,"DATASET"))} -> NAP | EU4: {=INDIRECT(ADDRESS(MATCH(ES4,DATASET!$K:$K,0),10,,,"DATASET"))} -> Por | EW4: TERRACCIANO | EX4: {=INDIRECT(ADDRESS(MATCH(EW4,DATASET!$K:$K,0),12,,,"DATASET"))} -> MIL | EY4: {=INDIRECT(ADDRESS(MATCH(EW4,DATASET!$K:$K,0),10,,,"DATASET"))} -> Por | FA4: PROVEDEL | FB4: {=INDIRECT(ADDRESS(MATCH(FA4,DATASET!$K:$K,0),12,,,"DATASET"))} -> LAZ | FC4: {=INDIRECT(ADDRESS(MATCH(FA4,DATASET!$K:$K,0),10,,,"DATASET"))} -> Por
A5: SPORTIELLO | B5: {=INDIRECT(ADDRESS(MATCH(A5,DATASET!$K:$K,0),12,,,"DATASET"))} -> ATA | C5: {=INDIRECT(ADDRESS(MATCH(A5,DATASET!$K:$K,0),10,,,"DATASET"))} -> Por | E5: VASQUEZ D. | F5: {=INDIRECT(ADDRESS(MATCH(E5,DATASET!$K:$K,0),12,,,"DATASET"))} -> ROM | G5: {=INDIRECT(ADDRESS(MATCH(E5,DATASET!$K:$K,0),10,,,"DATASET"))} -> Por | I5: TERRACCIANO | J5: {=INDIRECT(ADDRESS(MATCH(I5,DATASET!$K:$K,0),12,,,"DATASET"))} -> MIL | K5: {=INDIRECT(ADDRESS(MATCH(I5,DATASET!$K:$K,0),10,,,"DATASET"))} -> Por | M5: MILINKOVIC-SAVIC V. | N5: {=INDIRECT(ADDRESS(MATCH(M5,DATASET!$K:$K,0),12,,,"DATASET"))} -> NAP | O5: {=INDIRECT(ADDRESS(MATCH(M5,DATASET!$K:$K,0),10,,,"DATASET"))} -> Por | Q5: PINSOGLIO | R5: {=INDIRECT(ADDRESS(MATCH(Q5,DATASET!$K:$K,0),12,,,"DATASET"))} -> JUV | S5: {=INDIRECT(ADDRESS(MATCH(Q5,DATASET!$K:$K,0),10,,,"DATASET"))} -> Por | U5: SKORUPSKI | V5: {=INDIRECT(ADDRESS(MATCH(U5,DATASET!$K:$K,0),12,,,"DATASET"))} -> BOL | W5: {=INDIRECT(ADDRESS(MATCH(U5,DATASET!$K:$K,0),10,,,"DATASET"))} -> Por | Y5: MARTINELLI T. | Z5: {=INDIRECT(ADDRESS(MATCH(Y5,DATASET!$K:$K,0),12,,,"DATASET"))} -> FIO | AA5: {=INDIRECT(ADDRESS(MATCH(Y5,DATASET!$K:$K,0),10,,,"DATASET"))} -> Por | AC5: SOMMER | AD5: {=INDIRECT(ADDRESS(MATCH(AC5,DATASET!$K:$K,0),12,,,"DATASET"))} -> INT | AE5: {=INDIRECT(ADDRESS(MATCH(AC5,DATASET!$K:$K,0),10,,,"DATASET"))} -> Por | AG5: PROVEDEL | AH5: {=INDIRECT(ADDRESS(MATCH(AG5,DATASET!$K:$K,0),12,,,"DATASET"))} -> LAZ | AI5: {=INDIRECT(ADDRESS(MATCH(AG5,DATASET!$K:$K,0),10,,,"DATASET"))} -> Por | AK5: SUZUKI | AL5: {=INDIRECT(ADDRESS(MATCH(AK5,DATASET!$K:$K,0),12,,,"DATASET"))} -> PAR | AM5: {=INDIRECT(ADDRESS(MATCH(AK5,DATASET!$K:$K,0),10,,,"DATASET"))} -> Por | AO5: SUZUKI | AP5: {=INDIRECT(ADDRESS(MATCH(AO5,DATASET!$K:$K,0),12,,,"DATASET"))} -> PAR | AQ5: {=INDIRECT(ADDRESS(MATCH(AO5,DATASET!$K:$K,0),10,,,"DATASET"))} -> Por | AS5: SPORTIELLO | AT5: {=INDIRECT(ADDRESS(MATCH(AS5,DATASET!$K:$K,0),12,,,"DATASET"))} -> ATA | AU5: {=INDIRECT(ADDRESS(MATCH(AS5,DATASET!$K:$K,0),10,,,"DATASET"))} -> Por | AW5: PROVEDEL | AX5: {=INDIRECT(ADDRESS(MATCH(AW5,DATASET!$K:$K,0),12,,,"DATASET"))} -> LAZ | AY5: {=INDIRECT(ADDRESS(MATCH(AW5,DATASET!$K:$K,0),10,,,"DATASET"))} -> Por | BA5: MARTINELLI T. | BB5: {=INDIRECT(ADDRESS(MATCH(BA5,DATASET!$K:$K,0),12,,,"DATASET"))} -> FIO | BC5: {=INDIRECT(ADDRESS(MATCH(BA5,DATASET!$K:$K,0),10,,,"DATASET"))} -> Por | BE5: PERIN | BF5: {=INDIRECT(ADDRESS(MATCH(BE5,DATASET!$K:$K,0),12,,,"DATASET"))} -> JUV | BG5: {=INDIRECT(ADDRESS(MATCH(BE5,DATASET!$K:$K,0),10,,,"DATASET"))} -> Por | BI5: SOMMER | BJ5: {=INDIRECT(ADDRESS(MATCH(BI5,DATASET!$K:$K,0),12,,,"DATASET"))} -> INT | BK5: {=INDIRECT(ADDRESS(MATCH(BI5,DATASET!$K:$K,0),10,,,"DATASET"))} -> Por | BM5: SKORUPSKI | BN5: {=INDIRECT(ADDRESS(MATCH(BM5,DATASET!$K:$K,0),12,,,"DATASET"))} -> BOL | BO5: {=INDIRECT(ADDRESS(MATCH(BM5,DATASET!$K:$K,0),10,,,"DATASET"))} -> Por | BQ5: TURATI | BR5: {=INDIRECT(ADDRESS(MATCH(BQ5,DATASET!$K:$K,0),12,,,"DATASET"))} -> SAS | BS5: {=INDIRECT(ADDRESS(MATCH(BQ5,DATASET!$K:$K,0),10,,,"DATASET"))} -> Por | BU5: TERRACCIANO | BV5: {=INDIRECT(ADDRESS(MATCH(BU5,DATASET!$K:$K,0),12,,,"DATASET"))} -> MIL | BW5: {=INDIRECT(ADDRESS(MATCH(BU5,DATASET!$K:$K,0),10,,,"DATASET"))} -> Por | BY5: ZELEZNY | BZ5: {=INDIRECT(ADDRESS(MATCH(BY5,DATASET!$K:$K,0),12,,,"DATASET"))} -> ROM | CA5: {=INDIRECT(ADDRESS(MATCH(BY5,DATASET!$K:$K,0),10,,,"DATASET"))} -> Por | CC5: TORRIANI | CD5: {=INDIRECT(ADDRESS(MATCH(CC5,DATASET!$K:$K,0),12,,,"DATASET"))} -> MIL | CE5: {=INDIRECT(ADDRESS(MATCH(CC5,DATASET!$K:$K,0),10,,,"DATASET"))} -> Por | CG5: VASQUEZ D. | CH5: {=INDIRECT(ADDRESS(MATCH(CG5,DATASET!$K:$K,0),12,,,"DATASET"))} -> ROM | CI5: {=INDIRECT(ADDRESS(MATCH(CG5,DATASET!$K:$K,0),10,,,"DATASET"))} -> Por | CK5: SOMMER | CL5: {=INDIRECT(ADDRESS(MATCH(CK5,DATASET!$K:$K,0),12,,,"DATASET"))} -> INT | CM5: {=INDIRECT(ADDRESS(MATCH(CK5,DATASET!$K:$K,0),10,,,"DATASET"))} -> Por | CO5: LEALI | CP5: {=INDIRECT(ADDRESS(MATCH(CO5,DATASET!$K:$K,0),12,,,"DATASET"))} -> GEN | CQ5: {=INDIRECT(ADDRESS(MATCH(CO5,DATASET!$K:$K,0),10,,,"DATASET"))} -> Por | CS5: PROVEDEL | CT5: {=INDIRECT(ADDRESS(MATCH(CS5,DATASET!$K:$K,0),12,,,"DATASET"))} -> LAZ | CU5: {=INDIRECT(ADDRESS(MATCH(CS5,DATASET!$K:$K,0),10,,,"DATASET"))} -> Por | CW5: SUZUKI | CX5: {=INDIRECT(ADDRESS(MATCH(CW5,DATASET!$K:$K,0),12,,,"DATASET"))} -> PAR | CY5: {=INDIRECT(ADDRESS(MATCH(CW5,DATASET!$K:$K,0),10,,,"DATASET"))} -> Por | DA5: SKORUPSKI | DB5: {=INDIRECT(ADDRESS(MATCH(DA5,DATASET!$K:$K,0),12,,,"DATASET"))} -> BOL | DC5: {=INDIRECT(ADDRESS(MATCH(DA5,DATASET!$K:$K,0),10,,,"DATASET"))} -> Por | DE5: SKORUPSKI | DF5: {=INDIRECT(ADDRESS(MATCH(DE5,DATASET!$K:$K,0),12,,,"DATASET"))} -> BOL | DG5: {=INDIRECT(ADDRESS(MATCH(DE5,DATASET!$K:$K,0),10,,,"DATASET"))} -> Por | DI5: PERIN | DJ5: {=INDIRECT(ADDRESS(MATCH(DI5,DATASET!$K:$K,0),12,,,"DATASET"))} -> JUV | DK5: {=INDIRECT(ADDRESS(MATCH(DI5,DATASET!$K:$K,0),10,,,"DATASET"))} -> Por | DM5: MILINKOVIC-SAVIC V. | DN5: {=INDIRECT(ADDRESS(MATCH(DM5,DATASET!$K:$K,0),12,,,"DATASET"))} -> NAP | DO5: {=INDIRECT(ADDRESS(MATCH(DM5,DATASET!$K:$K,0),10,,,"DATASET"))} -> Por | DQ5: LEZZERINI | DR5: {=INDIRECT(ADDRESS(MATCH(DQ5,DATASET!$K:$K,0),12,,,"DATASET"))} -> FIO | DS5: {=INDIRECT(ADDRESS(MATCH(DQ5,DATASET!$K:$K,0),10,,,"DATASET"))} -> Por | DU5: ISRAEL | DV5: {=INDIRECT(ADDRESS(MATCH(DU5,DATASET!$K:$K,0),12,,,"DATASET"))} -> TOR | DW5: {=INDIRECT(ADDRESS(MATCH(DU5,DATASET!$K:$K,0),10,,,"DATASET"))} -> Por | DY5: SPORTIELLO | DZ5: {=INDIRECT(ADDRESS(MATCH(DY5,DATASET!$K:$K,0),12,,,"DATASET"))} -> ATA | EA5: {=INDIRECT(ADDRESS(MATCH(DY5,DATASET!$K:$K,0),10,,,"DATASET"))} -> Por | EC5: SOMMER | ED5: {=INDIRECT(ADDRESS(MATCH(EC5,DATASET!$K:$K,0),12,,,"DATASET"))} -> INT | EE5: {=INDIRECT(ADDRESS(MATCH(EC5,DATASET!$K:$K,0),10,,,"DATASET"))} -> Por | EG5: SKORUPSKI | EH5: {=INDIRECT(ADDRESS(MATCH(EG5,DATASET!$K:$K,0),12,,,"DATASET"))} -> BOL | EI5: {=INDIRECT(ADDRESS(MATCH(EG5,DATASET!$K:$K,0),10,,,"DATASET"))} -> Por | EK5: PINSOGLIO | EL5: {=INDIRECT(ADDRESS(MATCH(EK5,DATASET!$K:$K,0),12,,,"DATASET"))} -> JUV | EM5: {=INDIRECT(ADDRESS(MATCH(EK5,DATASET!$K:$K,0),10,,,"DATASET"))} -> Por | EO5: VASQUEZ D. | EP5: {=INDIRECT(ADDRESS(MATCH(EO5,DATASET!$K:$K,0),12,,,"DATASET"))} -> ROM | EQ5: {=INDIRECT(ADDRESS(MATCH(EO5,DATASET!$K:$K,0),10,,,"DATASET"))} -> Por | ES5: MILINKOVIC-SAVIC V. | ET5: {=INDIRECT(ADDRESS(MATCH(ES5,DATASET!$K:$K,0),12,,,"DATASET"))} -> NAP | EU5: {=INDIRECT(ADDRESS(MATCH(ES5,DATASET!$K:$K,0),10,,,"DATASET"))} -> Por | EW5: TORRIANI | EX5: {=INDIRECT(ADDRESS(MATCH(EW5,DATASET!$K:$K,0),12,,,"DATASET"))} -> MIL | EY5: {=INDIRECT(ADDRESS(MATCH(EW5,DATASET!$K:$K,0),10,,,"DATASET"))} -> Por | FA5: SUZUKI | FB5: {=INDIRECT(ADDRESS(MATCH(FA5,DATASET!$K:$K,0),12,,,"DATASET"))} -> PAR | FC5: {=INDIRECT(ADDRESS(MATCH(FA5,DATASET!$K:$K,0),10,,,"DATASET"))} -> Por
A6: CANDÈ | B6: {=INDIRECT(ADDRESS(MATCH(A6,DATASET!$K:$K,0),12,,,"DATASET"))} -> SAS | C6: {=INDIRECT(ADDRESS(MATCH(A6,DATASET!$K:$K,0),10,,,"DATASET"))} -> Dc, Ds | E6: CANESTRELLI | F6: {=INDIRECT(ADDRESS(MATCH(E6,DATASET!$K:$K,0),12,,,"DATASET"))} -> PIS | G6: {=INDIRECT(ADDRESS(MATCH(E6,DATASET!$K:$K,0),10,,,"DATASET"))} -> Dc | I6: BISSECK | J6: {=INDIRECT(ADDRESS(MATCH(I6,DATASET!$K:$K,0),12,,,"DATASET"))} -> INT | K6: {=INDIRECT(ADDRESS(MATCH(I6,DATASET!$K:$K,0),10,,,"DATASET"))} -> Dc | M6: ACERBI | N6: {=INDIRECT(ADDRESS(MATCH(M6,DATASET!$K:$K,0),12,,,"DATASET"))} -> INT | O6: {=INDIRECT(ADDRESS(MATCH(M6,DATASET!$K:$K,0),10,,,"DATASET"))} -> Dc | Q6: BERTOLA | R6: {=INDIRECT(ADDRESS(MATCH(Q6,DATASET!$K:$K,0),12,,,"DATASET"))} -> UDI | S6: {=INDIRECT(ADDRESS(MATCH(Q6,DATASET!$K:$K,0),10,,,"DATASET"))} -> Dc | U6: AKANJI | V6: {=INDIRECT(ADDRESS(MATCH(U6,DATASET!$K:$K,0),12,,,"DATASET"))} -> INT | W6: {=INDIRECT(ADDRESS(MATCH(U6,DATASET!$K:$K,0),10,,,"DATASET"))} -> Dc | Y6: BEUKEMA | Z6: {=INDIRECT(ADDRESS(MATCH(Y6,DATASET!$K:$K,0),12,,,"DATASET"))} -> NAP | AA6: {=INDIRECT(ADDRESS(MATCH(Y6,DATASET!$K:$K,0),10,,,"DATASET"))} -> Dc | AC6: BASCHIROTTO | AD6: {=INDIRECT(ADDRESS(MATCH(AC6,DATASET!$K:$K,0),12,,,"DATASET"))} -> CRE | AE6: {=INDIRECT(ADDRESS(MATCH(AC6,DATASET!$K:$K,0),10,,,"DATASET"))} -> Dc | AG6: DE WINTER | AH6: {=INDIRECT(ADDRESS(MATCH(AG6,DATASET!$K:$K,0),12,,,"DATASET"))} -> MIL | AI6: {=INDIRECT(ADDRESS(MATCH(AG6,DATASET!$K:$K,0),10,,,"DATASET"))} -> Dc, Dd | AK6: COMUZZO | AL6: {=INDIRECT(ADDRESS(MATCH(AK6,DATASET!$K:$K,0),12,,,"DATASET"))} -> FIO | AM6: {=INDIRECT(ADDRESS(MATCH(AK6,DATASET!$K:$K,0),10,,,"DATASET"))} -> Dc | AO6: ACERBI | AP6: {=INDIRECT(ADDRESS(MATCH(AO6,DATASET!$K:$K,0),12,,,"DATASET"))} -> INT | AQ6: {=INDIRECT(ADDRESS(MATCH(AO6,DATASET!$K:$K,0),10,,,"DATASET"))} -> Dc | AS6: KALULU | AT6: {=INDIRECT(ADDRESS(MATCH(AS6,DATASET!$K:$K,0),12,,,"DATASET"))} -> JUV | AU6: {=INDIRECT(ADDRESS(MATCH(AS6,DATASET!$K:$K,0),10,,,"DATASET"))} -> Dc, Dd | AW6: GASPAR K. | AX6: {=INDIRECT(ADDRESS(MATCH(AW6,DATASET!$K:$K,0),12,,,"DATASET"))} -> LEC | AY6: {=INDIRECT(ADDRESS(MATCH(AW6,DATASET!$K:$K,0),10,,,"DATASET"))} -> Dc | BA6: BASCHIROTTO | BB6: {=INDIRECT(ADDRESS(MATCH(BA6,DATASET!$K:$K,0),12,,,"DATASET"))} -> CRE | BC6: {=INDIRECT(ADDRESS(MATCH(BA6,DATASET!$K:$K,0),10,,,"DATASET"))} -> Dc | BE6: BASTONI | BF6: {=INDIRECT(ADDRESS(MATCH(BE6,DATASET!$K:$K,0),12,,,"DATASET"))} -> INT | BG6: {=INDIRECT(ADDRESS(MATCH(BE6,DATASET!$K:$K,0),10,,,"DATASET"))} -> Dc | BI6: COCO | BJ6: {=INDIRECT(ADDRESS(MATCH(BI6,DATASET!$K:$K,0),12,,,"DATASET"))} -> TOR | BK6: {=INDIRECT(ADDRESS(MATCH(BI6,DATASET!$K:$K,0),10,,,"DATASET"))} -> Dc | BM6: BUONGIORNO | BN6: {=INDIRECT(ADDRESS(MATCH(BM6,DATASET!$K:$K,0),12,,,"DATASET"))} -> NAP | BO6: {=INDIRECT(ADDRESS(MATCH(BM6,DATASET!$K:$K,0),10,,,"DATASET"))} -> Dc | BQ6: GABBIA | BR6: {=INDIRECT(ADDRESS(MATCH(BQ6,DATASET!$K:$K,0),12,,,"DATASET"))} -> MIL | BS6: {=INDIRECT(ADDRESS(MATCH(BQ6,DATASET!$K:$K,0),10,,,"DATASET"))} -> Dc | BU6: BEUKEMA | BV6: {=INDIRECT(ADDRESS(MATCH(BU6,DATASET!$K:$K,0),12,,,"DATASET"))} -> NAP | BW6: {=INDIRECT(ADDRESS(MATCH(BU6,DATASET!$K:$K,0),10,,,"DATASET"))} -> Dc | BY6: AKANJI | BZ6: {=INDIRECT(ADDRESS(MATCH(BY6,DATASET!$K:$K,0),12,,,"DATASET"))} -> INT | CA6: {=INDIRECT(ADDRESS(MATCH(BY6,DATASET!$K:$K,0),10,,,"DATASET"))} -> Dc | CC6: BASTONI | CD6: {=INDIRECT(ADDRESS(MATCH(CC6,DATASET!$K:$K,0),12,,,"DATASET"))} -> INT | CE6: {=INDIRECT(ADDRESS(MATCH(CC6,DATASET!$K:$K,0),10,,,"DATASET"))} -> Dc | CG6: BASCHIROTTO | CH6: {=INDIRECT(ADDRESS(MATCH(CG6,DATASET!$K:$K,0),12,,,"DATASET"))} -> CRE | CI6: {=INDIRECT(ADDRESS(MATCH(CG6,DATASET!$K:$K,0),10,,,"DATASET"))} -> Dc | CK6: CANESTRELLI | CL6: {=INDIRECT(ADDRESS(MATCH(CK6,DATASET!$K:$K,0),12,,,"DATASET"))} -> PIS | CM6: {=INDIRECT(ADDRESS(MATCH(CK6,DATASET!$K:$K,0),10,,,"DATASET"))} -> Dc | CO6: ACERBI | CP6: {=INDIRECT(ADDRESS(MATCH(CO6,DATASET!$K:$K,0),12,,,"DATASET"))} -> INT | CQ6: {=INDIRECT(ADDRESS(MATCH(CO6,DATASET!$K:$K,0),10,,,"DATASET"))} -> Dc | CS6: BIANCHETTI | CT6: {=INDIRECT(ADDRESS(MATCH(CS6,DATASET!$K:$K,0),12,,,"DATASET"))} -> CRE | CU6: {=INDIRECT(ADDRESS(MATCH(CS6,DATASET!$K:$K,0),10,,,"DATASET"))} -> Dc | CW6: GATTI | CX6: {=INDIRECT(ADDRESS(MATCH(CW6,DATASET!$K:$K,0),12,,,"DATASET"))} -> JUV | CY6: {=INDIRECT(ADDRESS(MATCH(CW6,DATASET!$K:$K,0),10,,,"DATASET"))} -> Dc | DA6: DE VRIJ | DB6: {=INDIRECT(ADDRESS(MATCH(DA6,DATASET!$K:$K,0),12,,,"DATASET"))} -> INT | DC6: {=INDIRECT(ADDRESS(MATCH(DA6,DATASET!$K:$K,0),10,,,"DATASET"))} -> Dc | DE6: ACERBI | DF6: {=INDIRECT(ADDRESS(MATCH(DE6,DATASET!$K:$K,0),12,,,"DATASET"))} -> INT | DG6: {=INDIRECT(ADDRESS(MATCH(DE6,DATASET!$K:$K,0),10,,,"DATASET"))} -> Dc | DI6: BERTOLA | DJ6: {=INDIRECT(ADDRESS(MATCH(DI6,DATASET!$K:$K,0),12,,,"DATASET"))} -> UDI | DK6: {=INDIRECT(ADDRESS(MATCH(DI6,DATASET!$K:$K,0),10,,,"DATASET"))} -> Dc | DM6: BISSECK | DN6: {=INDIRECT(ADDRESS(MATCH(DM6,DATASET!$K:$K,0),12,,,"DATASET"))} -> INT | DO6: {=INDIRECT(ADDRESS(MATCH(DM6,DATASET!$K:$K,0),10,,,"DATASET"))} -> Dc | DQ6: AKANJI | DR6: {=INDIRECT(ADDRESS(MATCH(DQ6,DATASET!$K:$K,0),12,,,"DATASET"))} -> INT | DS6: {=INDIRECT(ADDRESS(MATCH(DQ6,DATASET!$K:$K,0),10,,,"DATASET"))} -> Dc | DU6: BUONGIORNO | DV6: {=INDIRECT(ADDRESS(MATCH(DU6,DATASET!$K:$K,0),12,,,"DATASET"))} -> NAP | DW6: {=INDIRECT(ADDRESS(MATCH(DU6,DATASET!$K:$K,0),10,,,"DATASET"))} -> Dc | DY6: BASTONI | DZ6: {=INDIRECT(ADDRESS(MATCH(DY6,DATASET!$K:$K,0),12,,,"DATASET"))} -> INT | EA6: {=INDIRECT(ADDRESS(MATCH(DY6,DATASET!$K:$K,0),10,,,"DATASET"))} -> Dc | EC6: BREMER | ED6: {=INDIRECT(ADDRESS(MATCH(EC6,DATASET!$K:$K,0),12,,,"DATASET"))} -> JUV | EE6: {=INDIRECT(ADDRESS(MATCH(EC6,DATASET!$K:$K,0),10,,,"DATASET"))} -> Dc | EG6: BISSECK | EH6: {=INDIRECT(ADDRESS(MATCH(EG6,DATASET!$K:$K,0),12,,,"DATASET"))} -> INT | EI6: {=INDIRECT(ADDRESS(MATCH(EG6,DATASET!$K:$K,0),10,,,"DATASET"))} -> Dc | EK6: ACERBI | EL6: {=INDIRECT(ADDRESS(MATCH(EK6,DATASET!$K:$K,0),12,,,"DATASET"))} -> INT | EM6: {=INDIRECT(ADDRESS(MATCH(EK6,DATASET!$K:$K,0),10,,,"DATASET"))} -> Dc | EO6: BASCHIROTTO | EP6: {=INDIRECT(ADDRESS(MATCH(EO6,DATASET!$K:$K,0),12,,,"DATASET"))} -> CRE | EQ6: {=INDIRECT(ADDRESS(MATCH(EO6,DATASET!$K:$K,0),10,,,"DATASET"))} -> Dc | ES6: GASPAR K. | ET6: {=INDIRECT(ADDRESS(MATCH(ES6,DATASET!$K:$K,0),12,,,"DATASET"))} -> LEC | EU6: {=INDIRECT(ADDRESS(MATCH(ES6,DATASET!$K:$K,0),10,,,"DATASET"))} -> Dc | EW6: COCO | EX6: {=INDIRECT(ADDRESS(MATCH(EW6,DATASET!$K:$K,0),12,,,"DATASET"))} -> TOR | EY6: {=INDIRECT(ADDRESS(MATCH(EW6,DATASET!$K:$K,0),10,,,"DATASET"))} -> Dc | FA6: COMUZZO | FB6: {=INDIRECT(ADDRESS(MATCH(FA6,DATASET!$K:$K,0),12,,,"DATASET"))} -> FIO | FC6: {=INDIRECT(ADDRESS(MATCH(FA6,DATASET!$K:$K,0),10,,,"DATASET"))} -> Dc
A7: CARACCIOLO A. | B7: {=INDIRECT(ADDRESS(MATCH(A7,DATASET!$K:$K,0),12,,,"DATASET"))} -> PIS | C7: {=INDIRECT(ADDRESS(MATCH(A7,DATASET!$K:$K,0),10,,,"DATASET"))} -> Dc | E7: HIEN | F7: {=INDIRECT(ADDRESS(MATCH(E7,DATASET!$K:$K,0),12,,,"DATASET"))} -> ATA | G7: {=INDIRECT(ADDRESS(MATCH(E7,DATASET!$K:$K,0),10,,,"DATASET"))} -> Dc | I7: BUONGIORNO | J7: {=INDIRECT(ADDRESS(MATCH(I7,DATASET!$K:$K,0),12,,,"DATASET"))} -> NAP | K7: {=INDIRECT(ADDRESS(MATCH(I7,DATASET!$K:$K,0),10,,,"DATASET"))} -> Dc | M7: GABBIA | N7: {=INDIRECT(ADDRESS(MATCH(M7,DATASET!$K:$K,0),12,,,"DATASET"))} -> MIL | O7: {=INDIRECT(ADDRESS(MATCH(M7,DATASET!$K:$K,0),10,,,"DATASET"))} -> Dc | Q7: CIRCATI | R7: {=INDIRECT(ADDRESS(MATCH(Q7,DATASET!$K:$K,0),12,,,"DATASET"))} -> PAR | S7: {=INDIRECT(ADDRESS(MATCH(Q7,DATASET!$K:$K,0),10,,,"DATASET"))} -> Dc | U7: IDZES | V7: {=INDIRECT(ADDRESS(MATCH(U7,DATASET!$K:$K,0),12,,,"DATASET"))} -> SAS | W7: {=INDIRECT(ADDRESS(MATCH(U7,DATASET!$K:$K,0),10,,,"DATASET"))} -> Dc | Y7: BREMER | Z7: {=INDIRECT(ADDRESS(MATCH(Y7,DATASET!$K:$K,0),12,,,"DATASET"))} -> JUV | AA7: {=INDIRECT(ADDRESS(MATCH(Y7,DATASET!$K:$K,0),10,,,"DATASET"))} -> Dc | AC7: BASTONI | AD7: {=INDIRECT(ADDRESS(MATCH(AC7,DATASET!$K:$K,0),12,,,"DATASET"))} -> INT | AE7: {=INDIRECT(ADDRESS(MATCH(AC7,DATASET!$K:$K,0),10,,,"DATASET"))} -> Dc | AG7: GILA | AH7: {=INDIRECT(ADDRESS(MATCH(AG7,DATASET!$K:$K,0),12,,,"DATASET"))} -> LAZ | AI7: {=INDIRECT(ADDRESS(MATCH(AG7,DATASET!$K:$K,0),10,,,"DATASET"))} -> Dc | AK7: KELLY L. | AL7: {=INDIRECT(ADDRESS(MATCH(AK7,DATASET!$K:$K,0),12,,,"DATASET"))} -> JUV | AM7: {=INDIRECT(ADDRESS(MATCH(AK7,DATASET!$K:$K,0),10,,,"DATASET"))} -> Dc, Ds | AO7: BERTOLA | AP7: {=INDIRECT(ADDRESS(MATCH(AO7,DATASET!$K:$K,0),12,,,"DATASET"))} -> UDI | AQ7: {=INDIRECT(ADDRESS(MATCH(AO7,DATASET!$K:$K,0),10,,,"DATASET"))} -> Dc | AS7: KOSSOUNOU | AT7: {=INDIRECT(ADDRESS(MATCH(AS7,DATASET!$K:$K,0),12,,,"DATASET"))} -> ATA | AU7: {=INDIRECT(ADDRESS(MATCH(AS7,DATASET!$K:$K,0),10,,,"DATASET"))} -> Dc, Dd | AW7: GATTI | AX7: {=INDIRECT(ADDRESS(MATCH(AW7,DATASET!$K:$K,0),12,,,"DATASET"))} -> JUV | AY7: {=INDIRECT(ADDRESS(MATCH(AW7,DATASET!$K:$K,0),10,,,"DATASET"))} -> Dc | BA7: CARACCIOLO A. | BB7: {=INDIRECT(ADDRESS(MATCH(BA7,DATASET!$K:$K,0),12,,,"DATASET"))} -> PIS | BC7: {=INDIRECT(ADDRESS(MATCH(BA7,DATASET!$K:$K,0),10,,,"DATASET"))} -> Dc | BE7: DE WINTER | BF7: {=INDIRECT(ADDRESS(MATCH(BE7,DATASET!$K:$K,0),12,,,"DATASET"))} -> MIL | BG7: {=INDIRECT(ADDRESS(MATCH(BE7,DATASET!$K:$K,0),10,,,"DATASET"))} -> Dc, Dd | BI7: ISMAJLI | BJ7: {=INDIRECT(ADDRESS(MATCH(BI7,DATASET!$K:$K,0),12,,,"DATASET"))} -> TOR | BK7: {=INDIRECT(ADDRESS(MATCH(BI7,DATASET!$K:$K,0),10,,,"DATASET"))} -> Dc | BM7: DJIMSITI | BN7: {=INDIRECT(ADDRESS(MATCH(BM7,DATASET!$K:$K,0),12,,,"DATASET"))} -> ATA | BO7: {=INDIRECT(ADDRESS(MATCH(BM7,DATASET!$K:$K,0),10,,,"DATASET"))} -> Dc | BQ7: GHILARDI | BR7: {=INDIRECT(ADDRESS(MATCH(BQ7,DATASET!$K:$K,0),12,,,"DATASET"))} -> ROM | BS7: {=INDIRECT(ADDRESS(MATCH(BQ7,DATASET!$K:$K,0),10,,,"DATASET"))} -> Dc | BU7: BIANCHETTI | BV7: {=INDIRECT(ADDRESS(MATCH(BU7,DATASET!$K:$K,0),12,,,"DATASET"))} -> CRE | BW7: {=INDIRECT(ADDRESS(MATCH(BU7,DATASET!$K:$K,0),10,,,"DATASET"))} -> Dc | BY7: COMUZZO | BZ7: {=INDIRECT(ADDRESS(MATCH(BY7,DATASET!$K:$K,0),12,,,"DATASET"))} -> FIO | CA7: {=INDIRECT(ADDRESS(MATCH(BY7,DATASET!$K:$K,0),10,,,"DATASET"))} -> Dc | CC7: BEUKEMA | CD7: {=INDIRECT(ADDRESS(MATCH(CC7,DATASET!$K:$K,0),12,,,"DATASET"))} -> NAP | CE7: {=INDIRECT(ADDRESS(MATCH(CC7,DATASET!$K:$K,0),10,,,"DATASET"))} -> Dc | CG7: CIRCATI | CH7: {=INDIRECT(ADDRESS(MATCH(CG7,DATASET!$K:$K,0),12,,,"DATASET"))} -> PAR | CI7: {=INDIRECT(ADDRESS(MATCH(CG7,DATASET!$K:$K,0),10,,,"DATASET"))} -> Dc | CK7: KEMPF | CL7: {=INDIRECT(ADDRESS(MATCH(CK7,DATASET!$K:$K,0),12,,,"DATASET"))} -> COM | CM7: {=INDIRECT(ADDRESS(MATCH(CK7,DATASET!$K:$K,0),10,,,"DATASET"))} -> Dc | CO7: ALBIOL | CP7: {=INDIRECT(ADDRESS(MATCH(CO7,DATASET!$K:$K,0),12,,,"DATASET"))} -> PIS | CQ7: {=INDIRECT(ADDRESS(MATCH(CO7,DATASET!$K:$K,0),10,,,"DATASET"))} -> Dc | CS7: BUONGIORNO | CT7: {=INDIRECT(ADDRESS(MATCH(CS7,DATASET!$K:$K,0),12,,,"DATASET"))} -> NAP | CU7: {=INDIRECT(ADDRESS(MATCH(CS7,DATASET!$K:$K,0),10,,,"DATASET"))} -> Dc | CW7: ISMAJLI | CX7: {=INDIRECT(ADDRESS(MATCH(CW7,DATASET!$K:$K,0),12,,,"DATASET"))} -> TOR | CY7: {=INDIRECT(ADDRESS(MATCH(CW7,DATASET!$K:$K,0),10,,,"DATASET"))} -> Dc | DA7: DJIMSITI | DB7: {=INDIRECT(ADDRESS(MATCH(DA7,DATASET!$K:$K,0),12,,,"DATASET"))} -> ATA | DC7: {=INDIRECT(ADDRESS(MATCH(DA7,DATASET!$K:$K,0),10,,,"DATASET"))} -> Dc | DE7: BUONGIORNO | DF7: {=INDIRECT(ADDRESS(MATCH(DE7,DATASET!$K:$K,0),12,,,"DATASET"))} -> NAP | DG7: {=INDIRECT(ADDRESS(MATCH(DE7,DATASET!$K:$K,0),10,,,"DATASET"))} -> Dc | DI7: GASPAR K. | DJ7: {=INDIRECT(ADDRESS(MATCH(DI7,DATASET!$K:$K,0),12,,,"DATASET"))} -> LEC | DK7: {=INDIRECT(ADDRESS(MATCH(DI7,DATASET!$K:$K,0),10,,,"DATASET"))} -> Dc | DM7: DE WINTER | DN7: {=INDIRECT(ADDRESS(MATCH(DM7,DATASET!$K:$K,0),12,,,"DATASET"))} -> MIL | DO7: {=INDIRECT(ADDRESS(MATCH(DM7,DATASET!$K:$K,0),10,,,"DATASET"))} -> Dc, Dd | DQ7: BEUKEMA | DR7: {=INDIRECT(ADDRESS(MATCH(DQ7,DATASET!$K:$K,0),12,,,"DATASET"))} -> NAP | DS7: {=INDIRECT(ADDRESS(MATCH(DQ7,DATASET!$K:$K,0),10,,,"DATASET"))} -> Dc | DU7: CIRCATI | DV7: {=INDIRECT(ADDRESS(MATCH(DU7,DATASET!$K:$K,0),12,,,"DATASET"))} -> PAR | DW7: {=INDIRECT(ADDRESS(MATCH(DU7,DATASET!$K:$K,0),10,,,"DATASET"))} -> Dc | DY7: CANESTRELLI | DZ7: {=INDIRECT(ADDRESS(MATCH(DY7,DATASET!$K:$K,0),12,,,"DATASET"))} -> PIS | EA7: {=INDIRECT(ADDRESS(MATCH(DY7,DATASET!$K:$K,0),10,,,"DATASET"))} -> Dc | EC7: HIEN | ED7: {=INDIRECT(ADDRESS(MATCH(EC7,DATASET!$K:$K,0),12,,,"DATASET"))} -> ATA | EE7: {=INDIRECT(ADDRESS(MATCH(EC7,DATASET!$K:$K,0),10,,,"DATASET"))} -> Dc | EG7: EBOSSE | EH7: {=INDIRECT(ADDRESS(MATCH(EG7,DATASET!$K:$K,0),12,,,"DATASET"))} -> VER | EI7: {=INDIRECT(ADDRESS(MATCH(EG7,DATASET!$K:$K,0),10,,,"DATASET"))} -> Dc, Ds | EK7: BIANCHETTI | EL7: {=INDIRECT(ADDRESS(MATCH(EK7,DATASET!$K:$K,0),12,,,"DATASET"))} -> CRE | EM7: {=INDIRECT(ADDRESS(MATCH(EK7,DATASET!$K:$K,0),10,,,"DATASET"))} -> Dc | EO7: GABBIA | EP7: {=INDIRECT(ADDRESS(MATCH(EO7,DATASET!$K:$K,0),12,,,"DATASET"))} -> MIL | EQ7: {=INDIRECT(ADDRESS(MATCH(EO7,DATASET!$K:$K,0),10,,,"DATASET"))} -> Dc | ES7: KALULU | ET7: {=INDIRECT(ADDRESS(MATCH(ES7,DATASET!$K:$K,0),12,,,"DATASET"))} -> JUV | EU7: {=INDIRECT(ADDRESS(MATCH(ES7,DATASET!$K:$K,0),10,,,"DATASET"))} -> Dc, Dd | EW7: GATTI | EX7: {=INDIRECT(ADDRESS(MATCH(EW7,DATASET!$K:$K,0),12,,,"DATASET"))} -> JUV | EY7: {=INDIRECT(ADDRESS(MATCH(EW7,DATASET!$K:$K,0),10,,,"DATASET"))} -> Dc | FA7: IDZES | FB7: {=INDIRECT(ADDRESS(MATCH(FA7,DATASET!$K:$K,0),12,,,"DATASET"))} -> SAS | FC7: {=INDIRECT(ADDRESS(MATCH(FA7,DATASET!$K:$K,0),10,,,"DATASET"))} -> Dc
A8: GATTI | B8: {=INDIRECT(ADDRESS(MATCH(A8,DATASET!$K:$K,0),12,,,"DATASET"))} -> JUV | C8: {=INDIRECT(ADDRESS(MATCH(A8,DATASET!$K:$K,0),10,,,"DATASET"))} -> Dc | E8: MARIPAN | F8: {=INDIRECT(ADDRESS(MATCH(E8,DATASET!$K:$K,0),12,,,"DATASET"))} -> TOR | G8: {=INDIRECT(ADDRESS(MATCH(E8,DATASET!$K:$K,0),10,,,"DATASET"))} -> Dc | I8: HERMOSO | J8: {=INDIRECT(ADDRESS(MATCH(I8,DATASET!$K:$K,0),12,,,"DATASET"))} -> ROM | K8: {=INDIRECT(ADDRESS(MATCH(I8,DATASET!$K:$K,0),10,,,"DATASET"))} -> Dc | M8: KOSSOUNOU | N8: {=INDIRECT(ADDRESS(MATCH(M8,DATASET!$K:$K,0),12,,,"DATASET"))} -> ATA | O8: {=INDIRECT(ADDRESS(MATCH(M8,DATASET!$K:$K,0),10,,,"DATASET"))} -> Dc, Dd | Q8: LUPERTO | R8: {=INDIRECT(ADDRESS(MATCH(Q8,DATASET!$K:$K,0),12,,,"DATASET"))} -> CAG | S8: {=INDIRECT(ADDRESS(MATCH(Q8,DATASET!$K:$K,0),10,,,"DATASET"))} -> Dc | U8: KRISTENSEN T. | V8: {=INDIRECT(ADDRESS(MATCH(U8,DATASET!$K:$K,0),12,,,"DATASET"))} -> UDI | W8: {=INDIRECT(ADDRESS(MATCH(U8,DATASET!$K:$K,0),10,,,"DATASET"))} -> Dc, Dd | Y8: DE VRIJ | Z8: {=INDIRECT(ADDRESS(MATCH(Y8,DATASET!$K:$K,0),12,,,"DATASET"))} -> INT | AA8: {=INDIRECT(ADDRESS(MATCH(Y8,DATASET!$K:$K,0),10,,,"DATASET"))} -> Dc | AC8: BIANCHETTI | AD8: {=INDIRECT(ADDRESS(MATCH(AC8,DATASET!$K:$K,0),12,,,"DATASET"))} -> CRE | AE8: {=INDIRECT(ADDRESS(MATCH(AC8,DATASET!$K:$K,0),10,,,"DATASET"))} -> Dc | AG8: KALULU | AH8: {=INDIRECT(ADDRESS(MATCH(AG8,DATASET!$K:$K,0),12,,,"DATASET"))} -> JUV | AI8: {=INDIRECT(ADDRESS(MATCH(AG8,DATASET!$K:$K,0),10,,,"DATASET"))} -> Dc, Dd | AK8: PAVLOVIC | AL8: {=INDIRECT(ADDRESS(MATCH(AK8,DATASET!$K:$K,0),12,,,"DATASET"))} -> MIL | AM8: {=INDIRECT(ADDRESS(MATCH(AK8,DATASET!$K:$K,0),10,,,"DATASET"))} -> Dc | AO8: BREMER | AP8: {=INDIRECT(ADDRESS(MATCH(AO8,DATASET!$K:$K,0),12,,,"DATASET"))} -> JUV | AQ8: {=INDIRECT(ADDRESS(MATCH(AO8,DATASET!$K:$K,0),10,,,"DATASET"))} -> Dc | AS8: ROMAGNOLI | AT8: {=INDIRECT(ADDRESS(MATCH(AS8,DATASET!$K:$K,0),12,,,"DATASET"))} -> LAZ | AU8: {=INDIRECT(ADDRESS(MATCH(AS8,DATASET!$K:$K,0),10,,,"DATASET"))} -> Dc | AW8: MUHAREMOVIC | AX8: {=INDIRECT(ADDRESS(MATCH(AW8,DATASET!$K:$K,0),12,,,"DATASET"))} -> SAS | AY8: {=INDIRECT(ADDRESS(MATCH(AW8,DATASET!$K:$K,0),10,,,"DATASET"))} -> Dc | BA8: CIRCATI | BB8: {=INDIRECT(ADDRESS(MATCH(BA8,DATASET!$K:$K,0),12,,,"DATASET"))} -> PAR | BC8: {=INDIRECT(ADDRESS(MATCH(BA8,DATASET!$K:$K,0),10,,,"DATASET"))} -> Dc | BE8: MARIPAN | BF8: {=INDIRECT(ADDRESS(MATCH(BE8,DATASET!$K:$K,0),12,,,"DATASET"))} -> TOR | BG8: {=INDIRECT(ADDRESS(MATCH(BE8,DATASET!$K:$K,0),10,,,"DATASET"))} -> Dc | BI8: LUCUMÌ | BJ8: {=INDIRECT(ADDRESS(MATCH(BI8,DATASET!$K:$K,0),12,,,"DATASET"))} -> BOL | BK8: {=INDIRECT(ADDRESS(MATCH(BI8,DATASET!$K:$K,0),10,,,"DATASET"))} -> Dc | BM8: HIEN | BN8: {=INDIRECT(ADDRESS(MATCH(BM8,DATASET!$K:$K,0),12,,,"DATASET"))} -> ATA | BO8: {=INDIRECT(ADDRESS(MATCH(BM8,DATASET!$K:$K,0),10,,,"DATASET"))} -> Dc | BQ8: HERMOSO | BR8: {=INDIRECT(ADDRESS(MATCH(BQ8,DATASET!$K:$K,0),12,,,"DATASET"))} -> ROM | BS8: {=INDIRECT(ADDRESS(MATCH(BQ8,DATASET!$K:$K,0),10,,,"DATASET"))} -> Dc | BU8: BISSECK | BV8: {=INDIRECT(ADDRESS(MATCH(BU8,DATASET!$K:$K,0),12,,,"DATASET"))} -> INT | BW8: {=INDIRECT(ADDRESS(MATCH(BU8,DATASET!$K:$K,0),10,,,"DATASET"))} -> Dc | BY8: GILA | BZ8: {=INDIRECT(ADDRESS(MATCH(BY8,DATASET!$K:$K,0),12,,,"DATASET"))} -> LAZ | CA8: {=INDIRECT(ADDRESS(MATCH(BY8,DATASET!$K:$K,0),10,,,"DATASET"))} -> Dc | CC8: BREMER | CD8: {=INDIRECT(ADDRESS(MATCH(CC8,DATASET!$K:$K,0),12,,,"DATASET"))} -> JUV | CE8: {=INDIRECT(ADDRESS(MATCH(CC8,DATASET!$K:$K,0),10,,,"DATASET"))} -> Dc | CG8: HIEN | CH8: {=INDIRECT(ADDRESS(MATCH(CG8,DATASET!$K:$K,0),12,,,"DATASET"))} -> ATA | CI8: {=INDIRECT(ADDRESS(MATCH(CG8,DATASET!$K:$K,0),10,,,"DATASET"))} -> Dc | CK8: N'DICKA | CL8: {=INDIRECT(ADDRESS(MATCH(CK8,DATASET!$K:$K,0),12,,,"DATASET"))} -> ROM | CM8: {=INDIRECT(ADDRESS(MATCH(CK8,DATASET!$K:$K,0),10,,,"DATASET"))} -> Dc | CO8: MANCINI | CP8: {=INDIRECT(ADDRESS(MATCH(CO8,DATASET!$K:$K,0),12,,,"DATASET"))} -> ROM | CQ8: {=INDIRECT(ADDRESS(MATCH(CO8,DATASET!$K:$K,0),10,,,"DATASET"))} -> Dc | CS8: COCO | CT8: {=INDIRECT(ADDRESS(MATCH(CS8,DATASET!$K:$K,0),12,,,"DATASET"))} -> TOR | CU8: {=INDIRECT(ADDRESS(MATCH(CS8,DATASET!$K:$K,0),10,,,"DATASET"))} -> Dc | CW8: KRISTENSEN T. | CX8: {=INDIRECT(ADDRESS(MATCH(CW8,DATASET!$K:$K,0),12,,,"DATASET"))} -> UDI | CY8: {=INDIRECT(ADDRESS(MATCH(CW8,DATASET!$K:$K,0),10,,,"DATASET"))} -> Dc, Dd | DA8: IDZES | DB8: {=INDIRECT(ADDRESS(MATCH(DA8,DATASET!$K:$K,0),12,,,"DATASET"))} -> SAS | DC8: {=INDIRECT(ADDRESS(MATCH(DA8,DATASET!$K:$K,0),10,,,"DATASET"))} -> Dc | DE8: DJIMSITI | DF8: {=INDIRECT(ADDRESS(MATCH(DE8,DATASET!$K:$K,0),12,,,"DATASET"))} -> ATA | DG8: {=INDIRECT(ADDRESS(MATCH(DE8,DATASET!$K:$K,0),10,,,"DATASET"))} -> Dc | DI8: GILA | DJ8: {=INDIRECT(ADDRESS(MATCH(DI8,DATASET!$K:$K,0),12,,,"DATASET"))} -> LAZ | DK8: {=INDIRECT(ADDRESS(MATCH(DI8,DATASET!$K:$K,0),10,,,"DATASET"))} -> Dc | DM8: GABBIA | DN8: {=INDIRECT(ADDRESS(MATCH(DM8,DATASET!$K:$K,0),12,,,"DATASET"))} -> MIL | DO8: {=INDIRECT(ADDRESS(MATCH(DM8,DATASET!$K:$K,0),10,,,"DATASET"))} -> Dc | DQ8: DJIMSITI | DR8: {=INDIRECT(ADDRESS(MATCH(DQ8,DATASET!$K:$K,0),12,,,"DATASET"))} -> ATA | DS8: {=INDIRECT(ADDRESS(MATCH(DQ8,DATASET!$K:$K,0),10,,,"DATASET"))} -> Dc | DU8: DE VRIJ | DV8: {=INDIRECT(ADDRESS(MATCH(DU8,DATASET!$K:$K,0),12,,,"DATASET"))} -> INT | DW8: {=INDIRECT(ADDRESS(MATCH(DU8,DATASET!$K:$K,0),10,,,"DATASET"))} -> Dc | DY8: GHILARDI | DZ8: {=INDIRECT(ADDRESS(MATCH(DY8,DATASET!$K:$K,0),12,,,"DATASET"))} -> ROM | EA8: {=INDIRECT(ADDRESS(MATCH(DY8,DATASET!$K:$K,0),10,,,"DATASET"))} -> Dc | EC8: NELSSON | ED8: {=INDIRECT(ADDRESS(MATCH(EC8,DATASET!$K:$K,0),12,,,"DATASET"))} -> VER | EE8: {=INDIRECT(ADDRESS(MATCH(EC8,DATASET!$K:$K,0),10,,,"DATASET"))} -> Dc | EG8: GOGLICHIDZE | EH8: {=INDIRECT(ADDRESS(MATCH(EG8,DATASET!$K:$K,0),12,,,"DATASET"))} -> UDI | EI8: {=INDIRECT(ADDRESS(MATCH(EG8,DATASET!$K:$K,0),10,,,"DATASET"))} -> Dc, Dd | EK8: JUAN JESUS | EL8: {=INDIRECT(ADDRESS(MATCH(EK8,DATASET!$K:$K,0),12,,,"DATASET"))} -> NAP | EM8: {=INDIRECT(ADDRESS(MATCH(EK8,DATASET!$K:$K,0),10,,,"DATASET"))} -> Dc, Ds | EO8: ISMAJLI | EP8: {=INDIRECT(ADDRESS(MATCH(EO8,DATASET!$K:$K,0),12,,,"DATASET"))} -> TOR | EQ8: {=INDIRECT(ADDRESS(MATCH(EO8,DATASET!$K:$K,0),10,,,"DATASET"))} -> Dc | ES8: KELLY L. | ET8: {=INDIRECT(ADDRESS(MATCH(ES8,DATASET!$K:$K,0),12,,,"DATASET"))} -> JUV | EU8: {=INDIRECT(ADDRESS(MATCH(ES8,DATASET!$K:$K,0),10,,,"DATASET"))} -> Dc, Ds | EW8: HERMOSO | EX8: {=INDIRECT(ADDRESS(MATCH(EW8,DATASET!$K:$K,0),12,,,"DATASET"))} -> ROM | EY8: {=INDIRECT(ADDRESS(MATCH(EW8,DATASET!$K:$K,0),10,,,"DATASET"))} -> Dc | FA8: KEMPF | FB8: {=INDIRECT(ADDRESS(MATCH(FA8,DATASET!$K:$K,0),12,,,"DATASET"))} -> COM | FC8: {=INDIRECT(ADDRESS(MATCH(FA8,DATASET!$K:$K,0),10,,,"DATASET"))} -> Dc
A9: GOGLICHIDZE | B9: {=INDIRECT(ADDRESS(MATCH(A9,DATASET!$K:$K,0),12,,,"DATASET"))} -> UDI | C9: {=INDIRECT(ADDRESS(MATCH(A9,DATASET!$K:$K,0),10,,,"DATASET"))} -> Dc, Dd | E9: MUHAREMOVIC | F9: {=INDIRECT(ADDRESS(MATCH(E9,DATASET!$K:$K,0),12,,,"DATASET"))} -> SAS | G9: {=INDIRECT(ADDRESS(MATCH(E9,DATASET!$K:$K,0),10,,,"DATASET"))} -> Dc | I9: KEMPF | J9: {=INDIRECT(ADDRESS(MATCH(I9,DATASET!$K:$K,0),12,,,"DATASET"))} -> COM | K9: {=INDIRECT(ADDRESS(MATCH(I9,DATASET!$K:$K,0),10,,,"DATASET"))} -> Dc | M9: LUCUMÌ | N9: {=INDIRECT(ADDRESS(MATCH(M9,DATASET!$K:$K,0),12,,,"DATASET"))} -> BOL | O9: {=INDIRECT(ADDRESS(MATCH(M9,DATASET!$K:$K,0),10,,,"DATASET"))} -> Dc | Q9: MARCANDALLI | R9: {=INDIRECT(ADDRESS(MATCH(Q9,DATASET!$K:$K,0),12,,,"DATASET"))} -> GEN | S9: {=INDIRECT(ADDRESS(MATCH(Q9,DATASET!$K:$K,0),10,,,"DATASET"))} -> Dc | U9: MANCINI | V9: {=INDIRECT(ADDRESS(MATCH(U9,DATASET!$K:$K,0),12,,,"DATASET"))} -> ROM | W9: {=INDIRECT(ADDRESS(MATCH(U9,DATASET!$K:$K,0),10,,,"DATASET"))} -> Dc | Y9: ISMAJLI | Z9: {=INDIRECT(ADDRESS(MATCH(Y9,DATASET!$K:$K,0),12,,,"DATASET"))} -> TOR | AA9: {=INDIRECT(ADDRESS(MATCH(Y9,DATASET!$K:$K,0),10,,,"DATASET"))} -> Dc | AC9: COCO | AD9: {=INDIRECT(ADDRESS(MATCH(AC9,DATASET!$K:$K,0),12,,,"DATASET"))} -> TOR | AE9: {=INDIRECT(ADDRESS(MATCH(AC9,DATASET!$K:$K,0),10,,,"DATASET"))} -> Dc | AG9: N'DICKA | AH9: {=INDIRECT(ADDRESS(MATCH(AG9,DATASET!$K:$K,0),12,,,"DATASET"))} -> ROM | AI9: {=INDIRECT(ADDRESS(MATCH(AG9,DATASET!$K:$K,0),10,,,"DATASET"))} -> Dc | AK9: TOMORI | AL9: {=INDIRECT(ADDRESS(MATCH(AK9,DATASET!$K:$K,0),12,,,"DATASET"))} -> MIL | AM9: {=INDIRECT(ADDRESS(MATCH(AK9,DATASET!$K:$K,0),10,,,"DATASET"))} -> Dc | AO9: DE VRIJ | AP9: {=INDIRECT(ADDRESS(MATCH(AO9,DATASET!$K:$K,0),12,,,"DATASET"))} -> INT | AQ9: {=INDIRECT(ADDRESS(MATCH(AO9,DATASET!$K:$K,0),10,,,"DATASET"))} -> Dc | AS9: SCALVINI | AT9: {=INDIRECT(ADDRESS(MATCH(AS9,DATASET!$K:$K,0),12,,,"DATASET"))} -> ATA | AU9: {=INDIRECT(ADDRESS(MATCH(AS9,DATASET!$K:$K,0),10,,,"DATASET"))} -> Dc | AW9: PONGRACIC | AX9: {=INDIRECT(ADDRESS(MATCH(AW9,DATASET!$K:$K,0),12,,,"DATASET"))} -> FIO | AY9: {=INDIRECT(ADDRESS(MATCH(AW9,DATASET!$K:$K,0),10,,,"DATASET"))} -> Dc | BA9: NELSSON | BB9: {=INDIRECT(ADDRESS(MATCH(BA9,DATASET!$K:$K,0),12,,,"DATASET"))} -> VER | BC9: {=INDIRECT(ADDRESS(MATCH(BA9,DATASET!$K:$K,0),10,,,"DATASET"))} -> Dc | BE9: N'DICKA | BF9: {=INDIRECT(ADDRESS(MATCH(BE9,DATASET!$K:$K,0),12,,,"DATASET"))} -> ROM | BG9: {=INDIRECT(ADDRESS(MATCH(BE9,DATASET!$K:$K,0),10,,,"DATASET"))} -> Dc | BI9: COULIBALY W. | BJ9: {=INDIRECT(ADDRESS(MATCH(BI9,DATASET!$K:$K,0),12,,,"DATASET"))} -> SAS | BK9: {=INDIRECT(ADDRESS(MATCH(BI9,DATASET!$K:$K,0),10,,,"DATASET"))} -> Ds, Dd, E | BM9: LUPERTO | BN9: {=INDIRECT(ADDRESS(MATCH(BM9,DATASET!$K:$K,0),12,,,"DATASET"))} -> CAG | BO9: {=INDIRECT(ADDRESS(MATCH(BM9,DATASET!$K:$K,0),10,,,"DATASET"))} -> Dc | BQ9: MANCINI | BR9: {=INDIRECT(ADDRESS(MATCH(BQ9,DATASET!$K:$K,0),12,,,"DATASET"))} -> ROM | BS9: {=INDIRECT(ADDRESS(MATCH(BQ9,DATASET!$K:$K,0),10,,,"DATASET"))} -> Dc | BU9: CANESTRELLI | BV9: {=INDIRECT(ADDRESS(MATCH(BU9,DATASET!$K:$K,0),12,,,"DATASET"))} -> PIS | BW9: {=INDIRECT(ADDRESS(MATCH(BU9,DATASET!$K:$K,0),10,,,"DATASET"))} -> Dc | BY9: RAMON | BZ9: {=INDIRECT(ADDRESS(MATCH(BY9,DATASET!$K:$K,0),12,,,"DATASET"))} -> COM | CA9: {=INDIRECT(ADDRESS(MATCH(BY9,DATASET!$K:$K,0),10,,,"DATASET"))} -> Dc | CC9: RANIERI L. | CD9: {=INDIRECT(ADDRESS(MATCH(CC9,DATASET!$K:$K,0),12,,,"DATASET"))} -> FIO | CE9: {=INDIRECT(ADDRESS(MATCH(CC9,DATASET!$K:$K,0),10,,,"DATASET"))} -> Dc, Ds | CG9: KALULU | CH9: {=INDIRECT(ADDRESS(MATCH(CG9,DATASET!$K:$K,0),12,,,"DATASET"))} -> JUV | CI9: {=INDIRECT(ADDRESS(MATCH(CG9,DATASET!$K:$K,0),10,,,"DATASET"))} -> Dc, Dd | CK9: RAMON | CL9: {=INDIRECT(ADDRESS(MATCH(CK9,DATASET!$K:$K,0),12,,,"DATASET"))} -> COM | CM9: {=INDIRECT(ADDRESS(MATCH(CK9,DATASET!$K:$K,0),10,,,"DATASET"))} -> Dc | CO9: PONGRACIC | CP9: {=INDIRECT(ADDRESS(MATCH(CO9,DATASET!$K:$K,0),12,,,"DATASET"))} -> FIO | CQ9: {=INDIRECT(ADDRESS(MATCH(CO9,DATASET!$K:$K,0),10,,,"DATASET"))} -> Dc | CS9: HEGGEM | CT9: {=INDIRECT(ADDRESS(MATCH(CS9,DATASET!$K:$K,0),12,,,"DATASET"))} -> BOL | CU9: {=INDIRECT(ADDRESS(MATCH(CS9,DATASET!$K:$K,0),10,,,"DATASET"))} -> Dc, Ds | CW9: MINA | CX9: {=INDIRECT(ADDRESS(MATCH(CW9,DATASET!$K:$K,0),12,,,"DATASET"))} -> CAG | CY9: {=INDIRECT(ADDRESS(MATCH(CW9,DATASET!$K:$K,0),10,,,"DATASET"))} -> Dc | DA9: KOSSOUNOU | DB9: {=INDIRECT(ADDRESS(MATCH(DA9,DATASET!$K:$K,0),12,,,"DATASET"))} -> ATA | DC9: {=INDIRECT(ADDRESS(MATCH(DA9,DATASET!$K:$K,0),10,,,"DATASET"))} -> Dc, Dd | DE9: HIEN | DF9: {=INDIRECT(ADDRESS(MATCH(DE9,DATASET!$K:$K,0),12,,,"DATASET"))} -> ATA | DG9: {=INDIRECT(ADDRESS(MATCH(DE9,DATASET!$K:$K,0),10,,,"DATASET"))} -> Dc | DI9: HERMOSO | DJ9: {=INDIRECT(ADDRESS(MATCH(DI9,DATASET!$K:$K,0),12,,,"DATASET"))} -> ROM | DK9: {=INDIRECT(ADDRESS(MATCH(DI9,DATASET!$K:$K,0),10,,,"DATASET"))} -> Dc | DM9: KELLY L. | DN9: {=INDIRECT(ADDRESS(MATCH(DM9,DATASET!$K:$K,0),12,,,"DATASET"))} -> JUV | DO9: {=INDIRECT(ADDRESS(MATCH(DM9,DATASET!$K:$K,0),10,,,"DATASET"))} -> Dc, Ds | DQ9: GILA | DR9: {=INDIRECT(ADDRESS(MATCH(DQ9,DATASET!$K:$K,0),12,,,"DATASET"))} -> LAZ | DS9: {=INDIRECT(ADDRESS(MATCH(DQ9,DATASET!$K:$K,0),10,,,"DATASET"))} -> Dc | DU9: DE WINTER | DV9: {=INDIRECT(ADDRESS(MATCH(DU9,DATASET!$K:$K,0),12,,,"DATASET"))} -> MIL | DW9: {=INDIRECT(ADDRESS(MATCH(DU9,DATASET!$K:$K,0),10,,,"DATASET"))} -> Dc, Dd | DY9: HEGGEM | DZ9: {=INDIRECT(ADDRESS(MATCH(DY9,DATASET!$K:$K,0),12,,,"DATASET"))} -> BOL | EA9: {=INDIRECT(ADDRESS(MATCH(DY9,DATASET!$K:$K,0),10,,,"DATASET"))} -> Dc, Ds | EC9: WALUKIEWICZ | ED9: {=INDIRECT(ADDRESS(MATCH(EC9,DATASET!$K:$K,0),12,,,"DATASET"))} -> SAS | EE9: {=INDIRECT(ADDRESS(MATCH(EC9,DATASET!$K:$K,0),10,,,"DATASET"))} -> Dc, Dd | EG9: MINA | EH9: {=INDIRECT(ADDRESS(MATCH(EG9,DATASET!$K:$K,0),12,,,"DATASET"))} -> CAG | EI9: {=INDIRECT(ADDRESS(MATCH(EG9,DATASET!$K:$K,0),10,,,"DATASET"))} -> Dc | EK9: MATEUS LUSUARDI | EL9: {=INDIRECT(ADDRESS(MATCH(EK9,DATASET!$K:$K,0),12,,,"DATASET"))} -> PIS | EM9: {=INDIRECT(ADDRESS(MATCH(EK9,DATASET!$K:$K,0),10,,,"DATASET"))} -> Dc | EO9: LUPERTO | EP9: {=INDIRECT(ADDRESS(MATCH(EO9,DATASET!$K:$K,0),12,,,"DATASET"))} -> CAG | EQ9: {=INDIRECT(ADDRESS(MATCH(EO9,DATASET!$K:$K,0),10,,,"DATASET"))} -> Dc | ES9: KOSSOUNOU | ET9: {=INDIRECT(ADDRESS(MATCH(ES9,DATASET!$K:$K,0),12,,,"DATASET"))} -> ATA | EU9: {=INDIRECT(ADDRESS(MATCH(ES9,DATASET!$K:$K,0),10,,,"DATASET"))} -> Dc, Dd | EW9: MARIPAN | EX9: {=INDIRECT(ADDRESS(MATCH(EW9,DATASET!$K:$K,0),12,,,"DATASET"))} -> TOR | EY9: {=INDIRECT(ADDRESS(MATCH(EW9,DATASET!$K:$K,0),10,,,"DATASET"))} -> Dc | FA9: PAVLOVIC | FB9: {=INDIRECT(ADDRESS(MATCH(FA9,DATASET!$K:$K,0),12,,,"DATASET"))} -> MIL | FC9: {=INDIRECT(ADDRESS(MATCH(FA9,DATASET!$K:$K,0),10,,,"DATASET"))} -> Dc
